Workbook

Sheet Liquidacion Supervisores
B3: LIQUIDACION SEPTIEMBRE
R4: =+COUNTIF(R7:R9,"si") -> 3
F5: TIENDA PERFECTA 60% - Se liquida a partir del 60% | I5: VENTAS 20% - Se liquida a partir del 70% | L5: FECHAS CORTAS & DEVOLUCIONES 20% - Se liquida cumpl al 100% | P5: =+SUBTOTAL(9,P7:P9) -> 1120000
B6: LIDER | C6: LLAVE 1 CAPTURA | D6: LLAVE 2 COBERTURA | E6: PROM. LLAVE | F6: VALOR COMISION TP | G6: % CUMPL. TP | H6: VALOR COMISION | I6: VALOR COMISION VENTAS | J6: % VENTAS | K6: VALOR COMISION | L6: VALOR COMISION X FC DV | M6: % FC & DV | N6: VALOR COMISION | O6: Valor Comision | P6: Valor a Pagar | Q6: Comentario | R6: Cumple Llaves
B7: ANYI MAYERLIE ORJUELA | C7: =+VLOOKUP(B7,'TD Supervisores Y Lideres Prom'!$B$44:$D$48,2,FALSE) -> 0.97557689 | D7: =+VLOOKUP(B7,'TD Supervisores Y Lideres Prom'!$B$44:$D$48,3,FALSE) -> 0.98738761 | E7: =+AVERAGE(C7:D7) -> 0.98148225 | F7: =+O7*60% -> 240000 | G7: =+VLOOKUP(B7,'TD Supervisores Y Lideres Prom'!$B$20:$C$24,2,FALSE) -> 0.93861048 | H7: =IF(G7>80%,F7*100%,IF(AND(G7>=60%,G7<=79%),F7*60%,0)) -> 240000 | I7: =+O7*20% -> 80000 | J7: =+VLOOKUP(B7,'TD Supervisores Y Lideres Prom'!$B$20:$D$24,3,FALSE) -> 1.0805537 | K7: =IF(J7=70%,I7*70%,IF(AND(J7>=80%,J7<=90%),I7*80%,IF(AND(J7>=91%,J7<=95%),I7*90%,IF(J7=96%,I7*96%,IF(J7=97%,I7*97%,IF(J7=98%,I7*98%,IF(J7=99%,I7*99%,IF(J7>=100%,I7,0)))))))) -> 80000 | L7: =+O7*20% -> 80000 | M7: =+VLOOKUP(B7,'TD Supervisores Y Lideres Prom'!$B$20:$E$24,4,FALSE) -> 0.89409233 | N7: =+IF(M7=100%,L7,0) -> 0 | O7: 400000 | P7: =IF(R7="SI",SUM(H7,K7,N7),0) -> 320000 | R7: =IF(E7>=60%,"SI","NO") -> SI
B8: OSPINO ARAUJO ALEXANDER | C8: =+VLOOKUP(B8,'TD Supervisores Y Lideres Prom'!$B$44:$D$48,2,FALSE) -> 0.94750086 | D8: =+VLOOKUP(B8,'TD Supervisores Y Lideres Prom'!$B$44:$D$48,3,FALSE) -> 0.96118796 | E8: =+AVERAGE(C8:D8) -> 0.95434441 | F8: =+O8*60% -> 240000 | G8: =+VLOOKUP(B8,'TD Supervisores Y Lideres Prom'!$B$20:$C$24,2,FALSE) -> 0.87800853 | H8: =IF(G8>80%,F8*100%,IF(AND(G8>=60%,G8<=79%),F8*60%,0)) -> 240000 | I8: =+O8*20% -> 80000 | J8: =+VLOOKUP(B8,'TD Supervisores Y Lideres Prom'!$B$20:$D$24,3,FALSE) -> 1.0064851 | K8: =+I8*70% -> 56000 | L8: =+O8*20% -> 80000 | M8: =+VLOOKUP(B8,'TD Supervisores Y Lideres Prom'!$B$20:$E$24,4,FALSE) -> 0.81827385 | N8: =+IF(M8=100%,L8,0) -> 0 | O8: 400000 | P8: =+O8 -> 400000 | Q8: Ingreso el 18 Agosto / Pago pagarantizado Sept | R8: =IF(AND(C8>=70%,D8>=70%),"SI","NO") -> SI
B9: NATHALY AGUILAR | C9: =+VLOOKUP(B9,'TD Supervisores Y Lideres Prom'!$B$44:$D$48,2,FALSE) -> 0.95003768 | D9: =+VLOOKUP(B9,'TD Supervisores Y Lideres Prom'!$B$44:$D$48,3,FALSE) -> 0.95338013 | E9: =+AVERAGE(C9:D9) -> 0.95170891 | F9: =+O9*60% -> 240000 | G9: =+VLOOKUP(B9,'TD Supervisores Y Lideres Prom'!$B$20:$C$24,2,FALSE) -> 0.76785671 | H9: =IF(G9>80%,F9*100%,IF(AND(G9>=60%,G9<=79%),F9*60%,0)) -> 144000 | I9: =+O9*20% -> 80000 | J9: =+VLOOKUP(B9,'TD Supervisores Y Lideres Prom'!$B$20:$D$24,3,FALSE) -> 1.0809023 | K9: =IF(J9=70%,I9*70%,IF(AND(J9>=80%,J9<=90%),I9*80%,IF(AND(J9>=91%,J9<=95%),I9*90%,IF(J9=96%,I9*96%,IF(J9=97%,I9*97%,IF(J9=98%,I9*98%,IF(J9=99%,I9*99%,IF(J9>=100%,I9,0)))))))) -> 80000 | L9: =+O9*20% -> 80000 | M9: =+VLOOKUP(B9,'TD Supervisores Y Lideres Prom'!$B$20:$E$24,4,FALSE) -> 0.72472032 | N9: =+IF(M9=100%,L9,0) -> 0 | O9: 400000 | P9: =+O9 -> 400000 | Q9: Ingreso el 18 Agosto / Pago pagarantizado Sept | R9: =IF(E9>=60%,"SI","NO") -> SI
B10: Total general | F10: =+SUM(F7:F9) -> 720000 | H10: =+SUM(H7:H9) -> 624000 | I10: =+SUM(I7:I9) -> 240000 | K10: =+SUM(K7:K9) -> 216000 | L10: =+SUM(L7:L9) -> 240000 | N10: =+SUM(N7:N9) -> 0 | O10: =+SUM(O7:O9) -> 1200000 | P10: =+SUM(P7:P9) -> 1120000
Q12: CANT. | R12: =+COUNTIF(R16:R28,"si") -> 13
F14: TIENDA PERFECTA 60% - Se liquida a partir del 60% | I14: VENTAS 20% - Se liquida a partir del 70% | L14: FECHAS CORTAS & DEVOLUCIONES 20% - Se liquida cumpl al 100% | P14: =+SUBTOTAL(9,P16:P28) -> 3033748
B15: SUPERVISOR | C15: LLAVE 1 CAPTURA | D15: LLAVE 2 COBERTURA | E15: PROM. LLAVE | F15: VALOR COMISION TP | G15: % CUMPL. TP | H15: VALOR COMISION | I15: VALOR COMISION VENTAS | J15: % VENTAS | K15: VALOR COMISION | L15: VALOR COMISION X FC DV | M15: % FC & DV | N15: VALOR COMISION | O15: Valor Comision | P15: Valor a Pagar | Q15: Comentario | R15: Cumple Llaves
B16: GIL MARTINEZ JENNIFER STEFANNIE | C16: =+VLOOKUP(B16,'TD Supervisores Y Lideres Prom'!$B$27:$D$41,2,FALSE) -> 0.94895833 | D16: =+VLOOKUP(B16,'TD Supervisores Y Lideres Prom'!$B$27:$D$41,3,FALSE) -> 0.9828125 | E16: =+AVERAGE(C16:D16) -> 0.96588542 | F16: =+O16*60% -> 180000 | G16: =+VLOOKUP(B16,'TD Supervisores Y Lideres Prom'!$B$3:$C$17,2,FALSE) -> 0.92841435 | H16: =IF(G16>80%,F16*100%,IF(AND(G16>=60%,G16<=79%),F16*60%,0)) -> 180000 | I16: =+O16*20% -> 60000 | J16: =+VLOOKUP(B16,'TD Supervisores Y Lideres Prom'!$B$3:$D$17,3,FALSE) -> 1.076402 | K16: =IF(J16=70%,I16*70%,IF(AND(J16>=80%,J16<=90%),I16*80%,IF(AND(J16>=91%,J16<=95%),I16*90%,IF(J16=96%,I16*96%,IF(J16=97%,I16*97%,IF(J16=98%,I16*98%,IF(J16=99%,I16*99%,IF(J16>=100%,I16,0)))))))) -> 60000 | L16: =+O16*20% -> 60000 | M16: =+VLOOKUP(B16,'TD Supervisores Y Lideres Prom'!$B$3:$E$17,4,FALSE) -> 0.8703125 | N16: =+IF(M16=100%,L16,0) -> 0 | O16: 300000 | P16: =IF(R16="SI",SUM(H16,K16,N16),0) -> 240000 | R16: =IF(E16>=60%,"SI","NO") -> SI
B17: MELISA MARTINEZ | C17: =+VLOOKUP(B17,'TD Supervisores Y Lideres Prom'!$B$27:$D$41,2,FALSE) -> 0.97192982 | D17: =+VLOOKUP(B17,'TD Supervisores Y Lideres Prom'!$B$27:$D$41,3,FALSE) -> 1 | E17: =+AVERAGE(C17:D17) -> 0.98596491 | F17: =+O17*60% -> 180000 | G17: =+VLOOKUP(B17,'TD Supervisores Y Lideres Prom'!$B$3:$C$17,2,FALSE) -> 0.9237104 | H17: =IF(G17>80%,F17*100%,IF(AND(G17>=60%,G17<=79%),F17*60%,0)) -> 180000 | I17: =+O17*20% -> 60000 | J17: =+VLOOKUP(B17,'TD Supervisores Y Lideres Prom'!$B$3:$D$17,3,FALSE) -> 1.016199 | K17: =IF(J17=70%,I17*70%,IF(AND(J17>=80%,J17<=90%),I17*80%,IF(AND(J17>=91%,J17<=95%),I17*90%,IF(J17=96%,I17*96%,IF(J17=97%,I17*97%,IF(J17=98%,I17*98%,IF(J17=99%,I17*99%,IF(J17>=100%,I17,0)))))))) -> 60000 | L17: =+O17*20% -> 60000 | M17: =+VLOOKUP(B17,'TD Supervisores Y Lideres Prom'!$B$3:$E$17,4,FALSE) -> 1 | N17: =+IF(M17=100%,L17,0) -> 60000 | O17: 300000 | P17: =IF(R17="SI",SUM(H17,K17,N17),0) -> 300000 | R17: =IF(E17>=60%,"SI","NO") -> SI
B18: SUSANA SILVA MENDOZA | C18: =+VLOOKUP(B18,'TD Supervisores Y Lideres Prom'!$B$27:$D$41,2,FALSE) -> 0.95833333 | D18: =+VLOOKUP(B18,'TD Supervisores Y Lideres Prom'!$B$27:$D$41,3,FALSE) -> 0.96785714 | E18: =+AVERAGE(C18:D18) -> 0.96309524 | F18: =+O18*60% -> 180000 | G18: =+VLOOKUP(B18,'TD Supervisores Y Lideres Prom'!$B$3:$C$17,2,FALSE) -> 0.91865079 | H18: =IF(G18>80%,F18*100%,IF(AND(G18>=60%,G18<=79%),F18*60%,0)) -> 180000 | I18: =+O18*20% -> 60000 | J18: =+VLOOKUP(B18,'TD Supervisores Y Lideres Prom'!$B$3:$D$17,3,FALSE) -> 1.2615379 | K18: =IF(J18=70%,I18*70%,IF(AND(J18>=80%,J18<=90%),I18*80%,IF(AND(J18>=91%,J18<=95%),I18*90%,IF(J18=96%,I18*96%,IF(J18=97%,I18*97%,IF(J18=98%,I18*98%,IF(J18=99%,I18*99%,IF(J18>=100%,I18,0)))))))) -> 60000 | L18: =+O18*20% -> 60000 | M18: =+VLOOKUP(B18,'TD Supervisores Y Lideres Prom'!$B$3:$E$17,4,FALSE) -> 0.91964286 | N18: =+IF(M18=100%,L18,0) -> 0 | O18: 300000 | P18: =IF(R18="SI",SUM(H18,K18,N18),0) -> 240000 | R18: =IF(E18>=60%,"SI","NO") -> SI
B19: JUAN PABLO GIL ALMANZA | C19: =+VLOOKUP(B19,'TD Supervisores Y Lideres Prom'!$B$27:$D$41,2,FALSE) -> 0.99652778 | D19: =+VLOOKUP(B19,'TD Supervisores Y Lideres Prom'!$B$27:$D$41,3,FALSE) -> 1 | E19: =+AVERAGE(C19:D19) -> 0.99826389 | F19: =+O19*60% -> 180000 | G19: =+VLOOKUP(B19,'TD Supervisores Y Lideres Prom'!$B$3:$C$17,2,FALSE) -> 0.98833912 | H19: =IF(G19>80%,F19*100%,IF(AND(G19>=60%,G19<=79%),F19*60%,0)) -> 180000 | I19: =+O19*20% -> 60000 | J19: =+VLOOKUP(B19,'TD Supervisores Y Lideres Prom'!$B$3:$D$17,3,FALSE) -> 1.0212204 | K19: =IF(J19=70%,I19*70%,IF(AND(J19>=80%,J19<=90%),I19*80%,IF(AND(J19>=91%,J19<=95%),I19*90%,IF(J19=96%,I19*96%,IF(J19=97%,I19*97%,IF(J19=98%,I19*98%,IF(J19=99%,I19*99%,IF(J19>=100%,I19,0)))))))) -> 60000 | L19: =+O19*20% -> 60000 | M19: 0.97 | N19: =+IF(M19=100%,L19,0) -> 0 | O19: 300000 | P19: =IF(R19="SI",SUM(H19,K19,N19),0) -> 240000 | R19: =IF(E19>=60%,"SI","NO") -> SI
B20: PIÑEROS MONTAÑA LAURA ESTEPHANIA | C20: =+VLOOKUP(B20,'TD Supervisores Y Lideres Prom'!$B$27:$D$41,2,FALSE) -> 1 | D20: =+VLOOKUP(B20,'TD Supervisores Y Lideres Prom'!$B$27:$D$41,3,FALSE) -> 1 | E20: =+AVERAGE(C20:D20) -> 1 | F20: =+O20*60% -> 180000 | G20: =+VLOOKUP(B20,'TD Supervisores Y Lideres Prom'!$B$3:$C$17,2,FALSE) -> 0.97677962 | H20: =IF(G20>80%,F20*100%,IF(AND(G20>=60%,G20<=79%),F20*60%,0)) -> 180000 | I20: =+O20*20% -> 60000 | J20: =+VLOOKUP(B20,'TD Supervisores Y Lideres Prom'!$B$3:$D$17,3,FALSE) -> 1.0511249 | K20: =IF(J20=70%,I20*70%,IF(AND(J20>=80%,J20<=90%),I20*80%,IF(AND(J20>=91%,J20<=95%),I20*90%,IF(J20=96%,I20*96%,IF(J20=97%,I20*97%,IF(J20=98%,I20*98%,IF(J20=99%,I20*99%,IF(J20>=100%,I20,0)))))))) -> 60000 | L20: =+O20*20% -> 60000 | M20: =+VLOOKUP(B20,'TD Supervisores Y Lideres Prom'!$B$3:$E$17,4,FALSE) -> 0.85294118 | N20: =+IF(M20=100%,L20,0) -> 0 | O20: 300000 | P20: =IF(R20="SI",SUM(H20,K20,N20),0) -> 240000 | R20: =IF(E20>=60%,"SI","NO") -> SI
B21: MEJÍA BLANDÓN ASTRID KARINA | C21: =+VLOOKUP(B21,'TD Supervisores Y Lideres Prom'!$B$27:$D$41,2,FALSE) -> 0.91190853 | D21: =+VLOOKUP(B21,'TD Supervisores Y Lideres Prom'!$B$27:$D$41,3,FALSE) -> 0.9335258 | E21: =+AVERAGE(C21:D21) -> 0.92271716 | F21: =+O21*60% -> 180000 | G21: =+VLOOKUP(B21,'TD Supervisores Y Lideres Prom'!$B$3:$C$17,2,FALSE) -> 0.83148024 | H21: =IF(G21>80%,F21*100%,IF(AND(G21>=60%,G21<=79%),F21*60%,0)) -> 180000 | I21: =+O21*20% -> 60000 | J21: =+VLOOKUP(B21,'TD Supervisores Y Lideres Prom'!$B$3:$D$17,3,FALSE) -> 1.059624 | K21: =IF(J21=70%,I21*70%,IF(AND(J21>=80%,J21<=90%),I21*80%,IF(AND(J21>=91%,J21<=95%),I21*90%,IF(J21=96%,I21*96%,IF(J21=97%,I21*97%,IF(J21=98%,I21*98%,IF(J21=99%,I21*99%,IF(J21>=100%,I21,0)))))))) -> 60000 | L21: =+O21*20% -> 60000 | M21: =+VLOOKUP(B21,'TD Supervisores Y Lideres Prom'!$B$3:$E$17,4,FALSE) -> 0.85312654 | N21: =+IF(M21=100%,L21,0) -> 0 | O21: 300000 | P21: =IF(R21="SI",SUM(H21,K21,N21),0) -> 240000 | R21: =IF(E21>=60%,"SI","NO") -> SI
B22: PEREZ ZAGARRA AUGUSTO EDUARDO | C22: =+VLOOKUP(B22,'TD Supervisores Y Lideres Prom'!$B$27:$D$41,2,FALSE) -> 0.94542531 | D22: =+VLOOKUP(B22,'TD Supervisores Y Lideres Prom'!$B$27:$D$41,3,FALSE) -> 0.94385675 | E22: =+AVERAGE(C22:D22) -> 0.94464103 | F22: =+O22*60% -> 180000 | G22: =+VLOOKUP(B22,'TD Supervisores Y Lideres Prom'!$B$3:$C$17,2,FALSE) -> 0.81614188 | H22: =IF(G22>80%,F22*100%,IF(AND(G22>=60%,G22<=79%),F22*60%,0)) -> 180000 | I22: =+O22*20% -> 60000 | J22: 1 | K22: =IF(J22=70%,I22*70%,IF(AND(J22>=80%,J22<=90%),I22*80%,IF(AND(J22>=91%,J22<=95%),I22*90%,IF(J22=96%,I22*96%,IF(J22=97%,I22*97%,IF(J22=98%,I22*98%,IF(J22=99%,I22*99%,IF(J22>=100%,I22,0)))))))) -> 60000 | L22: =+O22*20% -> 60000 | M22: =+VLOOKUP(B22,'TD Supervisores Y Lideres Prom'!$B$3:$E$17,4,FALSE) -> 0.51912281 | N22: =+IF(M22=100%,L22,0) -> 0 | O22: 300000 | P22: =IF(R22="SI",SUM(H22,K22,N22),0) -> 240000 | R22: =IF(E22>=60%,"SI","NO") -> SI
B23: GONZALEZ BARRANTES EDWIN JESSID | C23: =+VLOOKUP(B23,'TD Supervisores Y Lideres Prom'!$B$27:$D$41,2,FALSE) -> 0.97476478 | D23: =+VLOOKUP(B23,'TD Supervisores Y Lideres Prom'!$B$27:$D$41,3,FALSE) -> 0.96919845 | E23: =+AVERAGE(C23:D23) -> 0.97198161 | F23: =+O23*60% -> 180000 | G23: =+VLOOKUP(B23,'TD Supervisores Y Lideres Prom'!$B$3:$C$17,2,FALSE) -> 0.89632471 | H23: =IF(G23>80%,F23*100%,IF(AND(G23>=60%,G23<=79%),F23*60%,0)) -> 180000 | I23: =+O23*20% -> 60000 | J23: =+VLOOKUP(B23,'TD Supervisores Y Lideres Prom'!$B$3:$D$17,3,FALSE) -> 1.0926129 | K23: =IF(J23=70%,I23*70%,IF(AND(J23>=80%,J23<=90%),I23*80%,IF(AND(J23>=91%,J23<=95%),I23*90%,IF(J23=96%,I23*96%,IF(J23=97%,I23*97%,IF(J23=98%,I23*98%,IF(J23=99%,I23*99%,IF(J23>=100%,I23,0)))))))) -> 60000 | L23: =+O23*20% -> 60000 | M23: 0.98 | N23: =+IF(M23=100%,L23,0) -> 0 | O23: 300000 | P23: =IF(R23="SI",SUM(H23,K23,N23),0) -> 240000 | R23: =IF(E23>=60%,"SI","NO") -> SI
B24: CAMPUZANO IRLET ANDREA | C24: =+VLOOKUP(B24,'TD Supervisores Y Lideres Prom'!$B$27:$D$41,2,FALSE) -> 0.96400401 | D24: =+VLOOKUP(B24,'TD Supervisores Y Lideres Prom'!$B$27:$D$41,3,FALSE) -> 0.96911765 | E24: =+AVERAGE(C24:D24) -> 0.96656083 | F24: =+O24*60% -> 180000 | G24: =+VLOOKUP(B24,'TD Supervisores Y Lideres Prom'!$B$3:$C$17,2,FALSE) -> 0.88866958 | H24: =IF(G24>80%,F24*100%,IF(AND(G24>=60%,G24<=79%),F24*60%,0)) -> 180000 | I24: =+O24*20% -> 60000 | J24: =+VLOOKUP(B24,'TD Supervisores Y Lideres Prom'!$B$3:$D$17,3,FALSE) -> 1.0799646 | K24: =IF(J24=70%,I24*70%,IF(AND(J24>=80%,J24<=90%),I24*80%,IF(AND(J24>=91%,J24<=95%),I24*90%,IF(J24=96%,I24*96%,IF(J24=97%,I24*97%,IF(J24=98%,I24*98%,IF(J24=99%,I24*99%,IF(J24>=100%,I24,0)))))))) -> 60000 | L24: =+O24*20% -> 60000 | M24: =+VLOOKUP(B24,'TD Supervisores Y Lideres Prom'!$B$3:$E$17,4,FALSE) -> 0.62376337 | N24: =+IF(M24=100%,L24,0) -> 0 | O24: 300000 | P24: =IF(R24="SI",SUM(H24,K24,N24),0) -> 240000 | R24: =IF(E24>=60%,"SI","NO") -> SI
B25: SÁNCHEZ ZAMBRANO LEIDY NICOLE VANESSA | C25: =+VLOOKUP(B25,'TD Supervisores Y Lideres Prom'!$B$27:$D$41,2,FALSE) -> 0.96398525 | D25: =+VLOOKUP(B25,'TD Supervisores Y Lideres Prom'!$B$27:$D$41,3,FALSE) -> 0.98823529 | E25: =+AVERAGE(C25:D25) -> 0.97611027 | F25: =+O25*60% -> 180000 | G25: =+VLOOKUP(B25,'TD Supervisores Y Lideres Prom'!$B$3:$C$17,2,FALSE) -> 0.93358847 | H25: =IF(G25>80%,F25*100%,IF(AND(G25>=60%,G25<=79%),F25*60%,0)) -> 180000 | I25: =+O25*20% -> 60000 | J25: =+VLOOKUP(B25,'TD Supervisores Y Lideres Prom'!$B$3:$D$17,3,FALSE) -> 0.96246619 | K25: =+I25*J25 -> 57747.971 | L25: =+O25*20% -> 60000 | M25: 0.81 | N25: =+IF(M25=100%,L25,0) -> 0 | O25: 300000 | P25: =IF(R25="SI",SUM(H25,K25,N25),0) -> 237747.97 | R25: =IF(E25>=60%,"SI","NO") -> SI
B26: OSSA TABARES JAZMIN BERNARDA | C26: =+VLOOKUP(B26,'TD Supervisores Y Lideres Prom'!$B$27:$D$41,2,FALSE) -> 0.96939988 | D26: =+VLOOKUP(B26,'TD Supervisores Y Lideres Prom'!$B$27:$D$41,3,FALSE) -> 0.97192513 | E26: =+AVERAGE(C26:D26) -> 0.97066251 | F26: =+O26*60% -> 180000 | G26: =+VLOOKUP(B26,'TD Supervisores Y Lideres Prom'!$B$3:$C$17,2,FALSE) -> 0.91319671 | H26: =IF(G26>80%,F26*100%,IF(AND(G26>=60%,G26<=79%),F26*60%,0)) -> 180000 | I26: =+O26*20% -> 60000 | J26: =+VLOOKUP(B26,'TD Supervisores Y Lideres Prom'!$B$3:$D$17,3,FALSE) -> 1.0183031 | K26: =IF(J26=70%,I26*70%,IF(AND(J26>=80%,J26<=90%),I26*80%,IF(AND(J26>=91%,J26<=95%),I26*90%,IF(J26=96%,I26*96%,IF(J26=97%,I26*97%,IF(J26=98%,I26*98%,IF(J26=99%,I26*99%,IF(J26>=100%,I26,0)))))))) -> 60000 | L26: =+O26*20% -> 60000 | M26: =+VLOOKUP(B26,'TD Supervisores Y Lideres Prom'!$B$3:$E$17,4,FALSE) -> 0.84581105 | N26: =+IF(M26=100%,L26,0) -> 0 | O26: 300000 | P26: =IF(R26="SI",SUM(H26,K26,N26),0) -> 240000 | R26: =IF(E26>=60%,"SI","NO") -> SI
B27: BOLAÑOS QUEVEDO ALEXIS | C27: =+VLOOKUP(B27,'TD Supervisores Y Lideres Prom'!$B$27:$D$41,2,FALSE) -> 0.94921105 | D27: =+VLOOKUP(B27,'TD Supervisores Y Lideres Prom'!$B$27:$D$41,3,FALSE) -> 0.94707429 | E27: =+AVERAGE(C27:D27) -> 0.94814267 | F27: =+O27*60% -> 180000 | G27: =+VLOOKUP(B27,'TD Supervisores Y Lideres Prom'!$B$3:$C$17,2,FALSE) -> 0.72334255 | H27: =IF(G27>80%,F27*100%,IF(AND(G27>=60%,G27<=79%),F27*60%,0)) -> 108000 | I27: =+O27*20% -> 60000 | J27: =+VLOOKUP(B27,'TD Supervisores Y Lideres Prom'!$B$3:$D$17,3,FALSE) -> 1.1272195 | K27: =IF(J27=70%,I27*70%,IF(AND(J27>=80%,J27<=90%),I27*80%,IF(AND(J27>=91%,J27<=95%),I27*90%,IF(J27=96%,I27*96%,IF(J27=97%,I27*97%,IF(J27=98%,I27*98%,IF(J27=99%,I27*99%,IF(J27>=100%,I27,0)))))))) -> 60000 | L27: =+O27*20% -> 60000 | M27: =+VLOOKUP(B27,'TD Supervisores Y Lideres Prom'!$B$3:$E$17,4,FALSE) -> 0.77506575 | N27: =+IF(M27=100%,L27,0) -> 0 | O27: 300000 | P27: =IF(R27="SI",SUM(H27,K27,N27),0) -> 168000 | R27: =IF(E27>=60%,"SI","NO") -> SI
B28: MARTINEZ VARGAS CHRISTAN RICARDO | C28: =+VLOOKUP(B28,'TD Supervisores Y Lideres Prom'!$B$27:$D$41,2,FALSE) -> 0.94012099 | D28: =+VLOOKUP(B28,'TD Supervisores Y Lideres Prom'!$B$27:$D$41,3,FALSE) -> 0.9475802 | E28: =+AVERAGE(C28:D28) -> 0.94385059 | F28: =+O28*60% -> 180000 | G28: =+VLOOKUP(B28,'TD Supervisores Y Lideres Prom'!$B$3:$C$17,2,FALSE) -> 0.71943788 | H28: =IF(G28>80%,F28*100%,IF(AND(G28>=60%,G28<=79%),F28*60%,0)) -> 108000 | I28: =+O28*20% -> 60000 | J28: =+VLOOKUP(B28,'TD Supervisores Y Lideres Prom'!$B$3:$D$17,3,FALSE) -> 1.0353063 | K28: =IF(J28=70%,I28*70%,IF(AND(J28>=80%,J28<=90%),I28*80%,IF(AND(J28>=91%,J28<=95%),I28*90%,IF(J28=96%,I28*96%,IF(J28=97%,I28*97%,IF(J28=98%,I28*98%,IF(J28=99%,I28*99%,IF(J28>=100%,I28,0)))))))) -> 60000 | L28: =+O28*20% -> 60000 | M28: =+VLOOKUP(B28,'TD Supervisores Y Lideres Prom'!$B$3:$E$17,4,FALSE) -> 0.75203408 | N28: =+IF(M28=100%,L28,0) -> 0 | O28: 300000 | P28: =IF(R28="SI",SUM(H28,K28,N28),0) -> 168000 | R28: =IF(E28>=60%,"SI","NO") -> SI
B29: Total general | F29: =+SUM(F16:F28) -> 2340000 | H29: =+SUM(H16:H28) -> 2196000 | I29: =+SUM(I16:I28) -> 780000 | K29: =+SUM(K16:K28) -> 777747.97 | L29: =+SUM(L16:L28) -> 780000 | N29: =+SUM(N16:N28) -> 60000 | O29: =+SUM(O16:O28) -> 3900000 | P29: =+SUM(P16:P28) -> 3033748
F33: TIENDA PERFECTA 60% - Se liquida a partir del 80% | I33: VENTAS 20% - Se liquida a partir del 80% | L33: FECHAS CORTAS & DEVOLUCIONES 20% - Se liquida cumpl al 100% | P33: =+SUBTOTAL(9,P35:P35) -> 320000 | R33: 1
B34: FORMADORA | C34: LLAVE 1 CAPTURA | D34: LLAVE 2 COBERTURA | E34: PROM. LLAVE | F34: VALOR COMISION TP | G34: % CUMPL. TP | H34: VALOR COMISION | I34: VALOR COMISION VENTAS | J34: % VENTAS | K34: VALOR COMISION | L34: VALOR COMISION X FC DV | M34: % FC & DV | N34: VALOR COMISION | O34: Valor Comision | P34: Valor a Pagar | Q34: Comentario | R34: Cumple Llaves
B35: SUSAN JULIETH CASTILLO PARRA | C35: =+C7 -> 0.97557689 | D35: =+D7 -> 0.98738761 | E35: =+E7 -> 0.98148225 | F35: =+F7 -> 240000 | G35: =+G7 -> 0.93861048 | H35: =+H7 -> 240000 | I35: =+I7 -> 80000 | J35: =+J7 -> 1.0805537 | ... N35: =+N7 -> 0 | O35: 250000 | P35: =+N35+K35+H35 -> 320000 | R35: =IF(E35>=60%,"SI","NO") -> SI
B36: Total general | F36: =+SUM(F35:F35) -> 240000 | H36: =+SUM(H35:H35) -> 240000 | I36: =+SUM(I35:I35) -> 80000 | K36: =+SUM(K35:K35) -> 80000 | L36: =+SUM(L35:L35) -> 80000 | N36: =+SUM(N35:N35) -> 0 | O36: =+SUM(O35:O35) -> 250000 | P36: =+SUM(P35:P35) -> 320000

Sheet TD Supervisores Y Lideres Prom
B2: SUPERVISORES
B3: COORDINADOR | C3: % Cumplimiento TP | D3: % Cumplimiento Ventas | E3: % Cumplimiento FC & DV | F3: Valor Comision
B4: GIL MARTINEZ JENNIFER STEFANNIE | C4: 0.92841435 | D4: 1.076402 | E4: 0.8703125 | F4: 300000
B5: MELISA MARTINEZ | C5: 0.9237104 | D5: 1.016199 | E5: 1 | F5: 300000
B6: SUSANA SILVA MENDOZA | C6: 0.91865079 | D6: 1.2615379 | E6: 0.91964286 | F6: 300000
B7: JUAN PABLO GIL ALMANZA | C7: 0.98833912 | D7: 1.0212204 | E7: 0.87326389 | F7: 300000
B8: PIÑEROS MONTAÑA LAURA ESTEPHANIA | C8: 0.97677962 | D8: 1.0511249 | E8: 0.85294118 | F8: 300000
B9: MEJÍA BLANDÓN ASTRID KARINA | C9: 0.83148024 | D9: 1.059624 | E9: 0.85312654 | F9: 300000
B10: PEREZ ZAGARRA AUGUSTO EDUARDO | C10: 0.81614188 | D10: 0.99506478 | E10: 0.51912281 | F10: 300000
B11: GONZALEZ BARRANTES EDWIN JESSID | C11: 0.89632471 | D11: 1.0926129 | E11: 0.83781872 | F11: 300000
B12: CAMPUZANO IRLET ANDREA | C12: 0.88866958 | D12: 1.0799646 | E12: 0.62376337 | F12: 300000
B13: SÁNCHEZ ZAMBRANO LEIDY NICOLE VANESSA | C13: 0.93358847 | D13: 0.96246619 | E13: 0.96532177 | F13: 300000
B14: OSSA TABARES JAZMIN BERNARDA | C14: 0.91319671 | D14: 1.0183031 | E14: 0.84581105 | F14: 300000
B15: BOLAÑOS QUEVEDO ALEXIS | C15: 0.72334255 | D15: 1.1272195 | E15: 0.77506575 | F15: 300000
B16: MARTINEZ VARGAS CHRISTAN RICARDO | C16: 0.71943788 | D16: 1.0353063 | E16: 0.75203408 | F16: 300000
B17: Total general | C17: 0.88882836 | D17: 1.0597394 | E17: 0.84028503 | F17: =+SUM(F4:F16) -> 3900000
B19: LIDERES
B20: COORDINADOR | C20: Promedio de % Cumplimiento TP | D20: Promedio de % Cumplimiento Ventas | E20: Promedio de % Cumplimiento FC & DV | F20: Valor Comision
B21: ANYI MAYERLIE ORJUELA | C21: 0.93861048 | D21: 1.0805537 | E21: 0.89409233 | F21: 400000
B22: OSPINO ARAUJO ALEXANDER | C22: 0.87800853 | D22: 1.0064851 | E22: 0.81827385 | F22: 400000
B23: NATHALY AGUILAR | C23: 0.76785671 | D23: 1.0809023 | E23: 0.72472032 | F23: 400000
B24: Total general | C24: 0.88882836 | D24: 1.0597394 | E24: 0.84028503
B26: SUPERVISORES
B27: COORDINADOR | C27: Promedio de % Cumpl. Captura | D27: Promedio de % Cumplimiento Cobertura
B28: GIL MARTINEZ JENNIFER STEFANNIE | C28: 0.94895833 | D28: 0.9828125
B29: MELISA MARTINEZ | C29: 0.97192982 | D29: 1
B30: SUSANA SILVA MENDOZA | C30: 0.95833333 | D30: 0.96785714
B31: JUAN PABLO GIL ALMANZA | C31: 0.99652778 | D31: 1
B32: PIÑEROS MONTAÑA LAURA ESTEPHANIA | C32: 1 | D32: 1
B33: MEJÍA BLANDÓN ASTRID KARINA | C33: 0.91190853 | D33: 0.9335258
B34: PEREZ ZAGARRA AUGUSTO EDUARDO | C34: 0.94542531 | D34: 0.94385675
B35: GONZALEZ BARRANTES EDWIN JESSID | C35: 0.97476478 | D35: 0.96919845
B36: CAMPUZANO IRLET ANDREA | C36: 0.96400401 | D36: 0.96911765
B37: SÁNCHEZ ZAMBRANO LEIDY NICOLE VANESSA | C37: 0.96398525 | D37: 0.98823529
B38: OSSA TABARES JAZMIN BERNARDA | C38: 0.96939988 | D38: 0.97192513
B39: BOLAÑOS QUEVEDO ALEXIS | C39: 0.94921105 | D39: 0.94707429
... B41: Total general | C41: 0.96277135 | D41: 0.97348947
B43: SUPERVISORES
B44: COORDINADOR | C44: Promedio de % Cumpl. Captura | D44: Promedio de % Cumplimiento Cobertura
B45: ANYI MAYERLIE ORJUELA | C45: 0.97557689 | D45: 0.98738761
...

Sheet Liquidacion Comision Septiembre
Y1: SI | Z1: =+COUNTIF(Y6:Y193,Y1) -> 188 | AA1: GANA REALMENTE | AB1: 187
B2: LIQUIDACION SEPTIEMBRE | Y2: Equipo ganador | Z2: =+Z1/188 -> 1 | AB2: =+AB1/188 -> 0.99468085
H3: LLAVE | J3: LLAVE | M3: 0.6 | Q3: 0.2 | U3: 0.2
G4: 250000 | H4: CAPTURA DE INFORMACION | M4: TIENDA PERFECTA | Q4: VENTAS | U4: DEVOLUCIONES & FECHAS CORTAS | Z4: =+SUBTOTAL(9,Z6:Z193) -> 39099920
B5: Regional | C5: RUTA | D5: Lider Alqueria | E5: Lider | F5: Supervisor | G5: Valor Comision | H5: % Cumpl. Captura | I5: Categoria Efec 60% | J5: % Cumplimiento Cobertura | K5: Categoria Efec 60% | L5: Promedio Llaves | M5: Valor Comision TP | N5: % Cumplimiento TP | O5: Categoria Efec >60% | P5: $ Liquidar | Q5: Valor Comision Ventas | R5: % Cumplimiento Ventas | S5: Categoria Efec | T5: $ Liquidar | U5: Valor Comision FC y Dev | V5: % Cumplimiento FC & DV | W5: Categoria Efec | X5: $ Liquidar | Y5: Corresponde Comision | Z5: Valor total A Pagar Real | AA5: Observaciones
B6: REGIONAL BOGOTA | C6: CTR_1 | D6: PAULA RUBIO | E6: ANYI MAYERLIE ORJUELA | F6: SUSANA SILVA MENDOZA | G6: =IF(L6>=80%,250000,IF(AND(L6>=60%,L6<80%),150000,0)) -> 250000 | H6: =+VLOOKUP(C6,Indicadores!B:C,2,FALSE) -> 1 | I6: =IF(H6>=60%,"Cumple","No Cumple") -> Cumple | J6: =+VLOOKUP(C6,Indicadores!B:F,5,FALSE) -> 1 | K6: =IF(J6>=60%,"Cumple","No Cumple") -> Cumple | L6: =+AVERAGE(H6,J6) -> 1 | M6: =+G6*$M$3 -> 150000 | N6: =+VLOOKUP(C6,Indicadores!B:M,12,FALSE) -> 1 | O6: =IF(N6>=60%,"Cumple","No Cumple") -> Cumple | P6: =IF(N6>80%,M6*100%,IF(AND(N6>=60%,N6<=79%),M6*60%,0)) -> 150000 | Q6: =+$G$6*$Q$3 -> 50000 | R6: =+IFERROR(VLOOKUP(C6,Indicadores!B:N,13,FALSE),0%) -> 1.0926436 | S6: =IF(R6>=70%,"Cumple","No Cumple") -> Cumple | T6: =IF(R6=80%,Q6*70%,IF(AND(R6>=81%,R6<=90%),Q6*80%,IF(AND(R6>=91%,R6<=95%),Q6*90%,IF(R6=96%,Q6*96%,IF(R6=97%,Q6*97%,IF(R6=98%,Q6*98%,IF(R6=99%,Q6*99%,IF(R6>=100%,Q6,0)))))))) -> 50000 | U6: =+G6*$U$3 -> 50000 | V6: =+VLOOKUP(C6,Indicadores!B:S,18,FALSE) -> 1 | W6: =IF(V6>=100%,"Cumple","No Cumple") -> Cumple | X6: =+IF(V6=100%,U6,0) -> 50000 | Y6: =IF(L6>=60%,"SI","NO") -> SI | Z6: =+IF(Y6="SI",P6+T6+X6,0) -> 250000
B7: REGIONAL BOGOTA | C7: CTR_10 | D7: PAULA RUBIO | E7: ANYI MAYERLIE ORJUELA | F7: SUSANA SILVA MENDOZA | G7: =IF(L7>=80%,250000,IF(AND(L7>=60%,L7<80%),150000,0)) -> 250000 | H7: =+VLOOKUP(C7,Indicadores!B:C,2,FALSE) -> 1 | I7: =IF(H7>=60%,"Cumple","No Cumple") -> Cumple | J7: =+VLOOKUP(C7,Indicadores!B:F,5,FALSE) -> 1 | K7: =IF(J7>=60%,"Cumple","No Cumple") -> Cumple | L7: =+AVERAGE(H7,J7) -> 1 | M7: =+G7*$M$3 -> 150000 | N7: =+VLOOKUP(C7,Indicadores!B:M,12,FALSE) -> 1 | O7: =IF(N7>=60%,"Cumple","No Cumple") -> Cumple | P7: =IF(N7>80%,M7*100%,IF(AND(N7>=60%,N7<=79%),M7*60%,0)) -> 150000 | Q7: =+$G$6*$Q$3 -> 50000 | R7: =+IFERROR(VLOOKUP(C7,Indicadores!B:N,13,FALSE),0%) -> 2.6859172 | S7: =IF(R7>=70%,"Cumple","No Cumple") -> Cumple | T7: =IF(R7=80%,Q7*70%,IF(AND(R7>=81%,R7<=90%),Q7*80%,IF(AND(R7>=91%,R7<=95%),Q7*90%,IF(R7=96%,Q7*96%,IF(R7=97%,Q7*97%,IF(R7=98%,Q7*98%,IF(R7=99%,Q7*99%,IF(R7>=100%,Q7,0)))))))) -> 50000 | U7: =+G7*$U$3 -> 50000 | V7: =+VLOOKUP(C7,Indicadores!B:S,18,FALSE) -> 1 | W7: =IF(V7>=100%,"Cumple","No Cumple") -> Cumple | X7: =+IF(V7=100%,U7,0) -> 50000 | Y7: =IF(L7>=60%,"SI","NO") -> SI | Z7: =+IF(Y7="SI",P7+T7+X7,0) -> 250000
B8: REGIONAL BOGOTA | C8: CTR_11 | D8: PAULA RUBIO | E8: ANYI MAYERLIE ORJUELA | F8: SUSANA SILVA MENDOZA | G8: =IF(L8>=80%,250000,IF(AND(L8>=60%,L8<80%),150000,0)) -> 250000 | H8: =+VLOOKUP(C8,Indicadores!B:C,2,FALSE) -> 0.91666667 | I8: =IF(H8>=60%,"Cumple","No Cumple") -> Cumple | J8: =+VLOOKUP(C8,Indicadores!B:F,5,FALSE) -> 0.91666667 | K8: =IF(J8>=60%,"Cumple","No Cumple") -> Cumple | L8: =+AVERAGE(H8,J8) -> 0.91666667 | M8: =+G8*$M$3 -> 150000 | N8: =+VLOOKUP(C8,Indicadores!B:M,12,FALSE) -> 0.94444444 | O8: =IF(N8>=60%,"Cumple","No Cumple") -> Cumple | P8: =IF(N8>80%,M8*100%,IF(AND(N8>=60%,N8<=79%),M8*60%,0)) -> 150000 | Q8: =+$G$6*$Q$3 -> 50000 | R8: =+IFERROR(VLOOKUP(C8,Indicadores!B:N,13,FALSE),0%) -> 1.1306234 | S8: =IF(R8>=70%,"Cumple","No Cumple") -> Cumple | T8: =IF(R8=80%,Q8*70%,IF(AND(R8>=81%,R8<=90%),Q8*80%,IF(AND(R8>=91%,R8<=95%),Q8*90%,IF(R8=96%,Q8*96%,IF(R8=97%,Q8*97%,IF(R8=98%,Q8*98%,IF(R8=99%,Q8*99%,IF(R8>=100%,Q8,0)))))))) -> 50000 | U8: =+G8*$U$3 -> 50000 | V8: =+VLOOKUP(C8,Indicadores!B:S,18,FALSE) -> 0.95833333 | W8: =IF(V8>=100%,"Cumple","No Cumple") -> No Cumple | X8: =+IF(V8=100%,U8,0) -> 0 | Y8: =IF(L8>=60%,"SI","NO") -> SI | Z8: =+IF(Y8="SI",P8+T8+X8,0) -> 200000
B9: REGIONAL BOGOTA | C9: CTR_12 | D9: PAULA RUBIO | E9: ANYI MAYERLIE ORJUELA | F9: SUSANA SILVA MENDOZA | G9: =IF(L9>=80%,250000,IF(AND(L9>=60%,L9<80%),150000,0)) -> 250000 | H9: =+VLOOKUP(C9,Indicadores!B:C,2,FALSE) -> 1 | I9: =IF(H9>=60%,"Cumple","No Cumple") -> Cumple | J9: =+VLOOKUP(C9,Indicadores!B:F,5,FALSE) -> 1 | K9: =IF(J9>=60%,"Cumple","No Cumple") -> Cumple | L9: =+AVERAGE(H9,J9) -> 1 | M9: =+G9*$M$3 -> 150000 | N9: =+VLOOKUP(C9,Indicadores!B:M,12,FALSE) -> 1 | O9: =IF(N9>=60%,"Cumple","No Cumple") -> Cumple | P9: =IF(N9>80%,M9*100%,IF(AND(N9>=60%,N9<=79%),M9*60%,0)) -> 150000 | Q9: =+$G$6*$Q$3 -> 50000 | R9: =+IFERROR(VLOOKUP(C9,Indicadores!B:N,13,FALSE),0%) -> 1.2889294 | S9: =IF(R9>=70%,"Cumple","No Cumple") -> Cumple | T9: =IF(R9=80%,Q9*70%,IF(AND(R9>=81%,R9<=90%),Q9*80%,IF(AND(R9>=91%,R9<=95%),Q9*90%,IF(R9=96%,Q9*96%,IF(R9=97%,Q9*97%,IF(R9=98%,Q9*98%,IF(R9=99%,Q9*99%,IF(R9>=100%,Q9,0)))))))) -> 50000 | U9: =+G9*$U$3 -> 50000 | V9: =+VLOOKUP(C9,Indicadores!B:S,18,FALSE) -> 1 | W9: =IF(V9>=100%,"Cumple","No Cumple") -> Cumple | X9: =+IF(V9=100%,U9,0) -> 50000 | Y9: =IF(L9>=60%,"SI","NO") -> SI | Z9: =+IF(Y9="SI",P9+T9+X9,0) -> 250000
B10: REGIONAL BOGOTA | C10: CTR_13 | D10: ALEJANDRO RODRIGUEZ | E10: ANYI MAYERLIE ORJUELA | F10: SUSANA SILVA MENDOZA | G10: =IF(L10>=80%,250000,IF(AND(L10>=60%,L10<80%),150000,0)) -> 250000 | H10: =+VLOOKUP(C10,Indicadores!B:C,2,FALSE) -> 1 | I10: =IF(H10>=60%,"Cumple","No Cumple") -> Cumple | J10: =+VLOOKUP(C10,Indicadores!B:F,5,FALSE) -> 1 | K10: =IF(J10>=60%,"Cumple","No Cumple") -> Cumple | L10: =+AVERAGE(H10,J10) -> 1 | M10: =+G10*$M$3 -> 150000 | N10: =+VLOOKUP(C10,Indicadores!B:M,12,FALSE) -> 1 | O10: =IF(N10>=60%,"Cumple","No Cumple") -> Cumple | P10: =IF(N10>80%,M10*100%,IF(AND(N10>=60%,N10<=79%),M10*60%,0)) -> 150000 | Q10: =+$G$6*$Q$3 -> 50000 | R10: =+IFERROR(VLOOKUP(C10,Indicadores!B:N,13,FALSE),0%) -> 1.1378459 | S10: =IF(R10>=70%,"Cumple","No Cumple") -> Cumple | T10: =IF(R10=80%,Q10*70%,IF(AND(R10>=81%,R10<=90%),Q10*80%,IF(AND(R10>=91%,R10<=95%),Q10*90%,IF(R10=96%,Q10*96%,IF(R10=97%,Q10*97%,IF(R10=98%,Q10*98%,IF(R10=99%,Q10*99%,IF(R10>=100%,Q10,0)))))))) -> 50000 | U10: =+G10*$U$3 -> 50000 | V10: =+VLOOKUP(C10,Indicadores!B:S,18,FALSE) -> 1 | W10: =IF(V10>=100%,"Cumple","No Cumple") -> Cumple | X10: =+IF(V10=100%,U10,0) -> 50000 | Y10: =IF(L10>=60%,"SI","NO") -> SI | Z10: =+IF(Y10="SI",P10+T10+X10,0) -> 250000
B11: REGIONAL BOGOTA | C11: CTR_14 | D11: PAULA RUBIO | E11: ANYI MAYERLIE ORJUELA | F11: SUSANA SILVA MENDOZA | G11: =IF(L11>=80%,250000,IF(AND(L11>=60%,L11<80%),150000,0)) -> 250000 | H11: =+VLOOKUP(C11,Indicadores!B:C,2,FALSE) -> 1 | I11: =IF(H11>=60%,"Cumple","No Cumple") -> Cumple | J11: =+VLOOKUP(C11,Indicadores!B:F,5,FALSE) -> 1 | K11: =IF(J11>=60%,"Cumple","No Cumple") -> Cumple | L11: =+AVERAGE(H11,J11) -> 1 | M11: =+G11*$M$3 -> 150000 | N11: =+VLOOKUP(C11,Indicadores!B:M,12,FALSE) -> 0.88888889 | O11: =IF(N11>=60%,"Cumple","No Cumple") -> Cumple | P11: =IF(N11>80%,M11*100%,IF(AND(N11>=60%,N11<=79%),M11*60%,0)) -> 150000 | Q11: =+$G$6*$Q$3 -> 50000 | R11: =+IFERROR(VLOOKUP(C11,Indicadores!B:N,13,FALSE),0%) -> 1.1051651 | S11: =IF(R11>=70%,"Cumple","No Cumple") -> Cumple | T11: =IF(R11=80%,Q11*70%,IF(AND(R11>=81%,R11<=90%),Q11*80%,IF(AND(R11>=91%,R11<=95%),Q11*90%,IF(R11=96%,Q11*96%,IF(R11=97%,Q11*97%,IF(R11=98%,Q11*98%,IF(R11=99%,Q11*99%,IF(R11>=100%,Q11,0)))))))) -> 50000 | U11: =+G11*$U$3 -> 50000 | V11: =+VLOOKUP(C11,Indicadores!B:S,18,FALSE) -> 0.5 | W11: =IF(V11>=100%,"Cumple","No Cumple") -> No Cumple | X11: =+IF(V11=100%,U11,0) -> 0 | Y11: =IF(L11>=60%,"SI","NO") -> SI | Z11: =+IF(Y11="SI",P11+T11+X11,0) -> 200000
B12: REGIONAL BOGOTA | C12: CTR_15 | D12: PAULA RUBIO | E12: ANYI MAYERLIE ORJUELA | F12: SUSANA SILVA MENDOZA | G12: =IF(L12>=80%,250000,IF(AND(L12>=60%,L12<80%),150000,0)) -> 250000 | H12: =+VLOOKUP(C12,Indicadores!B:C,2,FALSE) -> 1 | I12: =IF(H12>=60%,"Cumple","No Cumple") -> Cumple | J12: =+VLOOKUP(C12,Indicadores!B:F,5,FALSE) -> 1 | K12: =IF(J12>=60%,"Cumple","No Cumple") -> Cumple | L12: =+AVERAGE(H12,J12) -> 1 | M12: =+G12*$M$3 -> 150000 | N12: =+VLOOKUP(C12,Indicadores!B:M,12,FALSE) -> 0.95555556 | O12: =IF(N12>=60%,"Cumple","No Cumple") -> Cumple | P12: =IF(N12>80%,M12*100%,IF(AND(N12>=60%,N12<=79%),M12*60%,0)) -> 150000 | Q12: =+$G$6*$Q$3 -> 50000 | R12: =+IFERROR(VLOOKUP(C12,Indicadores!B:N,13,FALSE),0%) -> 1.1243968 | S12: =IF(R12>=70%,"Cumple","No Cumple") -> Cumple | T12: =IF(R12=80%,Q12*70%,IF(AND(R12>=81%,R12<=90%),Q12*80%,IF(AND(R12>=91%,R12<=95%),Q12*90%,IF(R12=96%,Q12*96%,IF(R12=97%,Q12*97%,IF(R12=98%,Q12*98%,IF(R12=99%,Q12*99%,IF(R12>=100%,Q12,0)))))))) -> 50000 | U12: =+G12*$U$3 -> 50000 | V12: =+VLOOKUP(C12,Indicadores!B:S,18,FALSE) -> 0.5 | W12: =IF(V12>=100%,"Cumple","No Cumple") -> No Cumple | X12: =+IF(V12=100%,U12,0) -> 0 | Y12: =IF(L12>=60%,"SI","NO") -> SI | Z12: =+IF(Y12="SI",P12+T12+X12,0) -> 200000
B13: REGIONAL BOGOTA | C13: CTR_16 | D13: PAULA RUBIO | E13: ANYI MAYERLIE ORJUELA | F13: SUSANA SILVA MENDOZA | G13: =IF(L13>=80%,250000,IF(AND(L13>=60%,L13<80%),150000,0)) -> 250000 | H13: =+VLOOKUP(C13,Indicadores!B:C,2,FALSE) -> 1 | I13: =IF(H13>=60%,"Cumple","No Cumple") -> Cumple | J13: =+VLOOKUP(C13,Indicadores!B:F,5,FALSE) -> 1 | K13: =IF(J13>=60%,"Cumple","No Cumple") -> Cumple | L13: =+AVERAGE(H13,J13) -> 1 | M13: =+G13*$M$3 -> 150000 | N13: =+VLOOKUP(C13,Indicadores!B:M,12,FALSE) -> 1 | O13: =IF(N13>=60%,"Cumple","No Cumple") -> Cumple | P13: =IF(N13>80%,M13*100%,IF(AND(N13>=60%,N13<=79%),M13*60%,0)) -> 150000 | Q13: =+$G$6*$Q$3 -> 50000 | R13: =+IFERROR(VLOOKUP(C13,Indicadores!B:N,13,FALSE),0%) -> 1.183968 | S13: =IF(R13>=70%,"Cumple","No Cumple") -> Cumple | T13: =IF(R13=80%,Q13*70%,IF(AND(R13>=81%,R13<=90%),Q13*80%,IF(AND(R13>=91%,R13<=95%),Q13*90%,IF(R13=96%,Q13*96%,IF(R13=97%,Q13*97%,IF(R13=98%,Q13*98%,IF(R13=99%,Q13*99%,IF(R13>=100%,Q13,0)))))))) -> 50000 | U13: =+G13*$U$3 -> 50000 | V13: =+VLOOKUP(C13,Indicadores!B:S,18,FALSE) -> 1 | W13: =IF(V13>=100%,"Cumple","No Cumple") -> Cumple | X13: =+IF(V13=100%,U13,0) -> 50000 | Y13: =IF(L13>=60%,"SI","NO") -> SI | Z13: =+IF(Y13="SI",P13+T13+X13,0) -> 250000
B14: REGIONAL BOGOTA | C14: CTR_2 | D14: FANNY FERNANDEZ | E14: ANYI MAYERLIE ORJUELA | F14: GIL MARTINEZ JENNIFER STEFANNIE | G14: =IF(L14>=80%,250000,IF(AND(L14>=60%,L14<80%),150000,0)) -> 250000 | H14: =+VLOOKUP(C14,Indicadores!B:C,2,FALSE) -> 1 | I14: =IF(H14>=60%,"Cumple","No Cumple") -> Cumple | J14: =+VLOOKUP(C14,Indicadores!B:F,5,FALSE) -> 1 | K14: =IF(J14>=60%,"Cumple","No Cumple") -> Cumple | L14: =+AVERAGE(H14,J14) -> 1 | M14: =+G14*$M$3 -> 150000 | N14: =+VLOOKUP(C14,Indicadores!B:M,12,FALSE) -> 1 | O14: =IF(N14>=60%,"Cumple","No Cumple") -> Cumple | P14: =IF(N14>80%,M14*100%,IF(AND(N14>=60%,N14<=79%),M14*60%,0)) -> 150000 | Q14: =+$G$6*$Q$3 -> 50000 | R14: =+IFERROR(VLOOKUP(C14,Indicadores!B:N,13,FALSE),0%) -> 1.1922166 | S14: =IF(R14>=70%,"Cumple","No Cumple") -> Cumple | T14: =IF(R14=80%,Q14*70%,IF(AND(R14>=81%,R14<=90%),Q14*80%,IF(AND(R14>=91%,R14<=95%),Q14*90%,IF(R14=96%,Q14*96%,IF(R14=97%,Q14*97%,IF(R14=98%,Q14*98%,IF(R14=99%,Q14*99%,IF(R14>=100%,Q14,0)))))))) -> 50000 | U14: =+G14*$U$3 -> 50000 | V14: =+VLOOKUP(C14,Indicadores!B:S,18,FALSE) -> 1 | W14: =IF(V14>=100%,"Cumple","No Cumple") -> Cumple | X14: =+IF(V14=100%,U14,0) -> 50000 | Y14: =IF(L14>=60%,"SI","NO") -> SI | Z14: =+IF(Y14="SI",P14+T14+X14,0) -> 250000
B15: REGIONAL BOGOTA | C15: CTR_3 | D15: FANNY FERNANDEZ | E15: ANYI MAYERLIE ORJUELA | F15: GIL MARTINEZ JENNIFER STEFANNIE | G15: =IF(L15>=80%,250000,IF(AND(L15>=60%,L15<80%),150000,0)) -> 150000 | H15: =+VLOOKUP(C15,Indicadores!B:C,2,FALSE) -> 0.33333333 | I15: =IF(H15>=60%,"Cumple","No Cumple") -> No Cumple | J15: =+VLOOKUP(C15,Indicadores!B:F,5,FALSE) -> 1 | K15: =IF(J15>=60%,"Cumple","No Cumple") -> Cumple | L15: =+AVERAGE(H15,J15) -> 0.66666667 | M15: =+G15*$M$3 -> 90000 | N15: =+VLOOKUP(C15,Indicadores!B:M,12,FALSE) -> 0.66666667 | O15: =IF(N15>=60%,"Cumple","No Cumple") -> Cumple | P15: =IF(N15>80%,M15*100%,IF(AND(N15>=60%,N15<=79%),M15*60%,0)) -> 54000 | Q15: =+$G$6*$Q$3 -> 50000 | R15: 1.1922 | S15: =IF(R15>=70%,"Cumple","No Cumple") -> Cumple | T15: =IF(R15=80%,Q15*70%,IF(AND(R15>=81%,R15<=90%),Q15*80%,IF(AND(R15>=91%,R15<=95%),Q15*90%,IF(R15=96%,Q15*96%,IF(R15=97%,Q15*97%,IF(R15=98%,Q15*98%,IF(R15=99%,Q15*99%,IF(R15>=100%,Q15,0)))))))) -> 50000 | U15: =+G15*$U$3 -> 30000 | V15: =+VLOOKUP(C15,Indicadores!B:S,18,FALSE) -> 1 | W15: =IF(V15>=100%,"Cumple","No Cumple") -> Cumple | X15: =+IF(V15=100%,U15,0) -> 30000 | Y15: =IF(L15>=60%,"SI","NO") -> SI | Z15: =+IF(Y15="SI",P15+T15+X15,0) -> 134000
B16: REGIONAL BOGOTA | C16: CTR_4 | D16: CAMILO RINCON | E16: ANYI MAYERLIE ORJUELA | F16: SUSANA SILVA MENDOZA | G16: =IF(L16>=80%,250000,IF(AND(L16>=60%,L16<80%),150000,0)) -> 250000 | H16: =+VLOOKUP(C16,Indicadores!B:C,2,FALSE) -> 1 | I16: =IF(H16>=60%,"Cumple","No Cumple") -> Cumple | J16: =+VLOOKUP(C16,Indicadores!B:F,5,FALSE) -> 1 | K16: =IF(J16>=60%,"Cumple","No Cumple") -> Cumple | L16: =+AVERAGE(H16,J16) -> 1 | M16: =+G16*$M$3 -> 150000 | N16: =+VLOOKUP(C16,Indicadores!B:M,12,FALSE) -> 0.58333333 | O16: =IF(N16>=60%,"Cumple","No Cumple") -> No Cumple | P16: =IF(N16>80%,M16*100%,IF(AND(N16>=60%,N16<=79%),M16*60%,0)) -> 0 | Q16: =+$G$6*$Q$3 -> 50000 | R16: =+IFERROR(VLOOKUP(C16,Indicadores!B:N,13,FALSE),0%) -> 1.5777985 | S16: =IF(R16>=70%,"Cumple","No Cumple") -> Cumple | T16: =IF(R16=80%,Q16*70%,IF(AND(R16>=81%,R16<=90%),Q16*80%,IF(AND(R16>=91%,R16<=95%),Q16*90%,IF(R16=96%,Q16*96%,IF(R16=97%,Q16*97%,IF(R16=98%,Q16*98%,IF(R16=99%,Q16*99%,IF(R16>=100%,Q16,0)))))))) -> 50000 | U16: =+G16*$U$3 -> 50000 | V16: =+VLOOKUP(C16,Indicadores!B:S,18,FALSE) -> 1 | W16: =IF(V16>=100%,"Cumple","No Cumple") -> Cumple | X16: =+IF(V16=100%,U16,0) -> 50000 | Y16: =IF(L16>=60%,"SI","NO") -> SI | Z16: =+IF(Y16="SI",P16+T16+X16,0) -> 100000
B17: REGIONAL BOGOTA | C17: CTR_5 | D17: CAMILO RINCON | E17: ANYI MAYERLIE ORJUELA | F17: SUSANA SILVA MENDOZA | G17: =IF(L17>=80%,250000,IF(AND(L17>=60%,L17<80%),150000,0)) -> 250000 | H17: =+VLOOKUP(C17,Indicadores!B:C,2,FALSE) -> 0.66666667 | I17: =IF(H17>=60%,"Cumple","No Cumple") -> Cumple | J17: =+VLOOKUP(C17,Indicadores!B:F,5,FALSE) -> 1 | K17: =IF(J17>=60%,"Cumple","No Cumple") -> Cumple | L17: =+AVERAGE(H17,J17) -> 0.83333333 | M17: =+G17*$M$3 -> 150000 | N17: =+VLOOKUP(C17,Indicadores!B:M,12,FALSE) -> 0.66666667 | O17: =IF(N17>=60%,"Cumple","No Cumple") -> Cumple | P17: =IF(N17>80%,M17*100%,IF(AND(N17>=60%,N17<=79%),M17*60%,0)) -> 90000 | Q17: =+$G$6*$Q$3 -> 50000 | R17: 1.5778 | S17: =IF(R17>=70%,"Cumple","No Cumple") -> Cumple | T17: =IF(R17=80%,Q17*70%,IF(AND(R17>=81%,R17<=90%),Q17*80%,IF(AND(R17>=91%,R17<=95%),Q17*90%,IF(R17=96%,Q17*96%,IF(R17=97%,Q17*97%,IF(R17=98%,Q17*98%,IF(R17=99%,Q17*99%,IF(R17>=100%,Q17,0)))))))) -> 50000 | U17: =+G17*$U$3 -> 50000 | V17: =+VLOOKUP(C17,Indicadores!B:S,18,FALSE) -> 1 | W17: =IF(V17>=100%,"Cumple","No Cumple") -> Cumple | X17: =+IF(V17=100%,U17,0) -> 50000 | Y17: =IF(L17>=60%,"SI","NO") -> SI | Z17: =+IF(Y17="SI",P17+T17+X17,0) -> 190000
B18: REGIONAL BOGOTA | C18: CTR_6 | D18: PAULA RUBIO | E18: ANYI MAYERLIE ORJUELA | F18: SUSANA SILVA MENDOZA | G18: =IF(L18>=80%,250000,IF(AND(L18>=60%,L18<80%),150000,0)) -> 250000 | H18: =+VLOOKUP(C18,Indicadores!B:C,2,FALSE) -> 1 | I18: =IF(H18>=60%,"Cumple","No Cumple") -> Cumple | J18: =+VLOOKUP(C18,Indicadores!B:F,5,FALSE) -> 0.8 | K18: =IF(J18>=60%,"Cumple","No Cumple") -> Cumple | L18: =+AVERAGE(H18,J18) -> 0.9 | M18: =+G18*$M$3 -> 150000 | N18: =+VLOOKUP(C18,Indicadores!B:M,12,FALSE) -> 0.93333333 | O18: =IF(N18>=60%,"Cumple","No Cumple") -> Cumple | P18: =IF(N18>80%,M18*100%,IF(AND(N18>=60%,N18<=79%),M18*60%,0)) -> 150000 | Q18: =+$G$6*$Q$3 -> 50000 | R18: =+IFERROR(VLOOKUP(C18,Indicadores!B:N,13,FALSE),0%) -> 0.98928991 | S18: =IF(R18>=70%,"Cumple","No Cumple") -> Cumple | T18: =IF(R18=80%,Q18*70%,IF(AND(R18>=81%,R18<=90%),Q18*80%,IF(AND(R18>=91%,R18<=95%),Q18*90%,IF(R18=96%,Q18*96%,IF(R18=97%,Q18*97%,IF(R18>=98%,Q18*98%,IF(R18=99%,Q18*99%,IF(R18>=100%,Q18,0)))))))) -> 49000 | U18: =+G18*$U$3 -> 50000 | V18: =+VLOOKUP(C18,Indicadores!B:S,18,FALSE) -> 1 | W18: =IF(V18>=100%,"Cumple","No Cumple") -> Cumple | X18: =+IF(V18=100%,U18,0) -> 50000 | Y18: =IF(L18>=60%,"SI","NO") -> SI | Z18: =+IF(Y18="SI",P18+T18+X18,0) -> 249000
B19: REGIONAL BOGOTA | C19: CTR_7 | D19: ALEJANDRO RODRIGUEZ | E19: ANYI MAYERLIE ORJUELA | F19: SUSANA SILVA MENDOZA | G19: =IF(L19>=80%,250000,IF(AND(L19>=60%,L19<80%),150000,0)) -> 250000 | H19: =+VLOOKUP(C19,Indicadores!B:C,2,FALSE) -> 1 | I19: =IF(H19>=60%,"Cumple","No Cumple") -> Cumple | J19: =+VLOOKUP(C19,Indicadores!B:F,5,FALSE) -> 1 | K19: =IF(J19>=60%,"Cumple","No Cumple") -> Cumple | L19: =+AVERAGE(H19,J19) -> 1 | M19: =+G19*$M$3 -> 150000 | N19: =+VLOOKUP(C19,Indicadores!B:M,12,FALSE) -> 1 | O19: =IF(N19>=60%,"Cumple","No Cumple") -> Cumple | P19: =IF(N19>80%,M19*100%,IF(AND(N19>=60%,N19<=79%),M19*60%,0)) -> 150000 | Q19: =+$G$6*$Q$3 -> 50000 | R19: =+IFERROR(VLOOKUP(C19,Indicadores!B:N,13,FALSE),0%) -> 1.0011239 | S19: =IF(R19>=70%,"Cumple","No Cumple") -> Cumple | T19: =IF(R19=80%,Q19*70%,IF(AND(R19>=81%,R19<=90%),Q19*80%,IF(AND(R19>=91%,R19<=95%),Q19*90%,IF(R19=96%,Q19*96%,IF(R19=97%,Q19*97%,IF(R19=98%,Q19*98%,IF(R19=99%,Q19*99%,IF(R19>=100%,Q19,0)))))))) -> 50000 | U19: =+G19*$U$3 -> 50000 | V19: =+VLOOKUP(C19,Indicadores!B:S,18,FALSE) -> 1 | W19: =IF(V19>=100%,"Cumple","No Cumple") -> Cumple | X19: =+IF(V19=100%,U19,0) -> 50000 | Y19: =IF(L19>=60%,"SI","NO") -> SI | Z19: =+IF(Y19="SI",P19+T19+X19,0) -> 250000
B20: REGIONAL BOGOTA | C20: CTR_8 | D20: CAMILO RINCON | E20: ANYI MAYERLIE ORJUELA | F20: SUSANA SILVA MENDOZA | G20: =IF(L20>=80%,250000,IF(AND(L20>=60%,L20<80%),150000,0)) -> 250000 | H20: =+VLOOKUP(C20,Indicadores!B:C,2,FALSE) -> 0.83333333 | I20: =IF(H20>=60%,"Cumple","No Cumple") -> Cumple | J20: =+VLOOKUP(C20,Indicadores!B:F,5,FALSE) -> 0.83333333 | K20: =IF(J20>=60%,"Cumple","No Cumple") -> Cumple | L20: =+AVERAGE(H20,J20) -> 0.83333333 | M20: =+G20*$M$3 -> 150000 | N20: =+VLOOKUP(C20,Indicadores!B:M,12,FALSE) -> 0.88888889 | O20: =IF(N20>=60%,"Cumple","No Cumple") -> Cumple | P20: =IF(N20>80%,M20*100%,IF(AND(N20>=60%,N20<=79%),M20*60%,0)) -> 150000 | Q20: =+$G$6*$Q$3 -> 50000 | R20: =+IFERROR(VLOOKUP(C20,Indicadores!B:N,13,FALSE),0%) -> 1.0138425 | S20: =IF(R20>=70%,"Cumple","No Cumple") -> Cumple | T20: =IF(R20=80%,Q20*70%,IF(AND(R20>=81%,R20<=90%),Q20*80%,IF(AND(R20>=91%,R20<=95%),Q20*90%,IF(R20=96%,Q20*96%,IF(R20=97%,Q20*97%,IF(R20=98%,Q20*98%,IF(R20=99%,Q20*99%,IF(R20>=100%,Q20,0)))))))) -> 50000 | U20: =+G20*$U$3 -> 50000 | V20: =+VLOOKUP(C20,Indicadores!B:S,18,FALSE) -> 0.91666667 | W20: =IF(V20>=100%,"Cumple","No Cumple") -> No Cumple | X20: =+IF(V20=100%,U20,0) -> 0 | Y20: =IF(L20>=60%,"SI","NO") -> SI | Z20: =+IF(Y20="SI",P20+T20+X20,0) -> 200000
B21: REGIONAL BOGOTA | C21: CTR_9 | D21: ALEJANDRO RODRIGUEZ | E21: ANYI MAYERLIE ORJUELA | F21: SUSANA SILVA MENDOZA | G21: =IF(L21>=80%,250000,IF(AND(L21>=60%,L21<80%),150000,0)) -> 250000 | H21: =+VLOOKUP(C21,Indicadores!B:C,2,FALSE) -> 1 | I21: =IF(H21>=60%,"Cumple","No Cumple") -> Cumple | J21: =+VLOOKUP(C21,Indicadores!B:F,5,FALSE) -> 1 | K21: =IF(J21>=60%,"Cumple","No Cumple") -> Cumple | L21: =+AVERAGE(H21,J21) -> 1 | M21: =+G21*$M$3 -> 150000 | N21: =+VLOOKUP(C21,Indicadores!B:M,12,FALSE) -> 1 | O21: =IF(N21>=60%,"Cumple","No Cumple") -> Cumple | P21: =IF(N21>80%,M21*100%,IF(AND(N21>=60%,N21<=79%),M21*60%,0)) -> 150000 | Q21: =+$G$6*$Q$3 -> 50000 | R21: =+IFERROR(VLOOKUP(C21,Indicadores!B:N,13,FALSE),0%) -> 0.75218714 | S21: =IF(R21>=80%,"Cumple","No Cumple") -> No Cumple | T21: =IF(R21>=70%,Q21*70%,IF(AND(R21>=81%,R21<=90%),Q21*80%,IF(AND(R21>=91%,R21<=95%),Q21*90%,IF(R21=96%,Q21*96%,IF(R21=97%,Q21*97%,IF(R21=98%,Q21*98%,IF(R21=99%,Q21*99%,IF(R21>=100%,Q21,0)))))))) -> 35000 | U21: =+G21*$U$3 -> 50000 | V21: =+VLOOKUP(C21,Indicadores!B:S,18,FALSE) -> 1 | W21: =IF(V21>=100%,"Cumple","No Cumple") -> Cumple | X21: =+IF(V21=100%,U21,0) -> 50000 | Y21: =IF(L21>=60%,"SI","NO") -> SI | Z21: =+IF(Y21="SI",P21+T21+X21,0) -> 235000
B22: REGIONAL BOGOTA | C22: SOR_1 | D22: ALEJANDRO RODRIGUEZ | E22: ANYI MAYERLIE ORJUELA | F22: JUAN PABLO GIL ALMANZA | G22: =IF(L22>=80%,250000,IF(AND(L22>=60%,L22<80%),150000,0)) -> 250000 | H22: =+VLOOKUP(C22,Indicadores!B:C,2,FALSE) -> 1 | I22: =IF(H22>=60%,"Cumple","No Cumple") -> Cumple | J22: =+VLOOKUP(C22,Indicadores!B:F,5,FALSE) -> 1 | K22: =IF(J22>=60%,"Cumple","No Cumple") -> Cumple | L22: =+AVERAGE(H22,J22) -> 1 | M22: =+G22*$M$3 -> 150000 | N22: =+VLOOKUP(C22,Indicadores!B:M,12,FALSE) -> 1 | O22: =IF(N22>=60%,"Cumple","No Cumple") -> Cumple | P22: =IF(N22>80%,M22*100%,IF(AND(N22>=60%,N22<=79%),M22*60%,0)) -> 150000 | Q22: =+$G$6*$Q$3 -> 50000 | R22: =+IFERROR(VLOOKUP(C22,Indicadores!B:N,13,FALSE),0%) -> 1.1783685 | S22: =IF(R22>=70%,"Cumple","No Cumple") -> Cumple | T22: =IF(R22=80%,Q22*70%,IF(AND(R22>=81%,R22<=90%),Q22*80%,IF(AND(R22>=91%,R22<=95%),Q22*90%,IF(R22=96%,Q22*96%,IF(R22=97%,Q22*97%,IF(R22=98%,Q22*98%,IF(R22=99%,Q22*99%,IF(R22>=100%,Q22,0)))))))) -> 50000 | U22: =+G22*$U$3 -> 50000 | V22: =+VLOOKUP(C22,Indicadores!B:S,18,FALSE) -> 1 | W22: =IF(V22>=100%,"Cumple","No Cumple") -> Cumple | X22: =+IF(V22=100%,U22,0) -> 50000 | Y22: =IF(L22>=60%,"SI","NO") -> SI | Z22: =+IF(Y22="SI",P22+T22+X22,0) -> 250000
B23: REGIONAL BOGOTA | C23: SOR_10 | D23: ALEJANDRO RODRIGUEZ | E23: ANYI MAYERLIE ORJUELA | F23: JUAN PABLO GIL ALMANZA | G23: =IF(L23>=80%,250000,IF(AND(L23>=60%,L23<80%),150000,0)) -> 250000 | H23: =+VLOOKUP(C23,Indicadores!B:C,2,FALSE) -> 1 | I23: =IF(H23>=60%,"Cumple","No Cumple") -> Cumple | J23: =+VLOOKUP(C23,Indicadores!B:F,5,FALSE) -> 1 | K23: =IF(J23>=60%,"Cumple","No Cumple") -> Cumple | L23: =+AVERAGE(H23,J23) -> 1 | M23: =+G23*$M$3 -> 150000 | N23: =+VLOOKUP(C23,Indicadores!B:M,12,FALSE) -> 0.875 | O23: =IF(N23>=60%,"Cumple","No Cumple") -> Cumple | P23: =IF(N23>80%,M23*100%,IF(AND(N23>=60%,N23<=79%),M23*60%,0)) -> 150000 | Q23: =+$G$6*$Q$3 -> 50000 | R23: =+IFERROR(VLOOKUP(C23,Indicadores!B:N,13,FALSE),0%) -> 1.0265769 | S23: =IF(R23>=70%,"Cumple","No Cumple") -> Cumple | T23: =IF(R23=80%,Q23*70%,IF(AND(R23>=81%,R23<=90%),Q23*80%,IF(AND(R23>=91%,R23<=95%),Q23*90%,IF(R23=96%,Q23*96%,IF(R23=97%,Q23*97%,IF(R23=98%,Q23*98%,IF(R23=99%,Q23*99%,IF(R23>=100%,Q23,0)))))))) -> 50000 | U23: =+G23*$U$3 -> 50000 | V23: =+VLOOKUP(C23,Indicadores!B:S,18,FALSE) -> 1 | W23: =IF(V23>=100%,"Cumple","No Cumple") -> Cumple | X23: =+IF(V23=100%,U23,0) -> 50000 | Y23: =IF(L23>=60%,"SI","NO") -> SI | Z23: =+IF(Y23="SI",P23+T23+X23,0) -> 250000
B24: REGIONAL BOGOTA | C24: SOR_11 | D24: ALEJANDRO RODRIGUEZ | E24: ANYI MAYERLIE ORJUELA | F24: JUAN PABLO GIL ALMANZA | G24: =IF(L24>=80%,250000,IF(AND(L24>=60%,L24<80%),150000,0)) -> 250000 | H24: =+VLOOKUP(C24,Indicadores!B:C,2,FALSE) -> 1 | I24: =IF(H24>=60%,"Cumple","No Cumple") -> Cumple | J24: =+VLOOKUP(C24,Indicadores!B:F,5,FALSE) -> 1 | K24: =IF(J24>=60%,"Cumple","No Cumple") -> Cumple | L24: =+AVERAGE(H24,J24) -> 1 | M24: =+G24*$M$3 -> 150000 | N24: =+VLOOKUP(C24,Indicadores!B:M,12,FALSE) -> 0.97916667 | O24: =IF(N24>=60%,"Cumple","No Cumple") -> Cumple | P24: =IF(N24>80%,M24*100%,IF(AND(N24>=60%,N24<=79%),M24*60%,0)) -> 150000 | Q24: =+$G$6*$Q$3 -> 50000 | R24: =+IFERROR(VLOOKUP(C24,Indicadores!B:N,13,FALSE),0%) -> 0.93665487 | S24: =IF(R24>=70%,"Cumple","No Cumple") -> Cumple | T24: =IF(R24=80%,Q24*70%,IF(AND(R24>=81%,R24<=90%),Q24*80%,IF(AND(R24>=91%,R24<=95%),Q24*90%,IF(R24=96%,Q24*96%,IF(R24=97%,Q24*97%,IF(R24=98%,Q24*98%,IF(R24=99%,Q24*99%,IF(R24>=100%,Q24,0)))))))) -> 45000 | U24: =+G24*$U$3 -> 50000 | V24: =+VLOOKUP(C24,Indicadores!B:S,18,FALSE) -> 1 | W24: =IF(V24>=100%,"Cumple","No Cumple") -> Cumple | X24: =+IF(V24=100%,U24,0) -> 50000 | Y24: =IF(L24>=60%,"SI","NO") -> SI | Z24: =+IF(Y24="SI",P24+T24+X24,0) -> 245000
B25: REGIONAL BOGOTA | C25: SOR_12 | D25: PAULA RUBIO | E25: ANYI MAYERLIE ORJUELA | F25: JUAN PABLO GIL ALMANZA | G25: =IF(L25>=80%,250000,IF(AND(L25>=60%,L25<80%),150000,0)) -> 250000 | H25: =+VLOOKUP(C25,Indicadores!B:C,2,FALSE) -> 1 | I25: =IF(H25>=60%,"Cumple","No Cumple") -> Cumple | J25: =+VLOOKUP(C25,Indicadores!B:F,5,FALSE) -> 1 | K25: =IF(J25>=60%,"Cumple","No Cumple") -> Cumple | L25: =+AVERAGE(H25,J25) -> 1 | M25: =+G25*$M$3 -> 150000 | N25: =+VLOOKUP(C25,Indicadores!B:M,12,FALSE) -> 1 | O25: =IF(N25>=60%,"Cumple","No Cumple") -> Cumple | P25: =IF(N25>80%,M25*100%,IF(AND(N25>=60%,N25<=79%),M25*60%,0)) -> 150000 | Q25: =+$G$6*$Q$3 -> 50000 | R25: =+IFERROR(VLOOKUP(C25,Indicadores!B:N,13,FALSE),0%) -> 1.0490627 | S25: =IF(R25>=70%,"Cumple","No Cumple") -> Cumple | T25: =IF(R25=80%,Q25*70%,IF(AND(R25>=81%,R25<=90%),Q25*80%,IF(AND(R25>=91%,R25<=95%),Q25*90%,IF(R25=96%,Q25*96%,IF(R25=97%,Q25*97%,IF(R25=98%,Q25*98%,IF(R25=99%,Q25*99%,IF(R25>=100%,Q25,0)))))))) -> 50000 | U25: =+G25*$U$3 -> 50000 | V25: =+VLOOKUP(C25,Indicadores!B:S,18,FALSE) -> 1 | W25: =IF(V25>=100%,"Cumple","No Cumple") -> Cumple | X25: =+IF(V25=100%,U25,0) -> 50000 | Y25: =IF(L25>=60%,"SI","NO") -> SI | Z25: =+IF(Y25="SI",P25+T25+X25,0) -> 250000
B26: REGIONAL BOGOTA | C26: SOR_13 | D26: ALEJANDRO RODRIGUEZ | E26: ANYI MAYERLIE ORJUELA | F26: JUAN PABLO GIL ALMANZA | G26: =IF(L26>=80%,250000,IF(AND(L26>=60%,L26<80%),150000,0)) -> 250000 | H26: =+VLOOKUP(C26,Indicadores!B:C,2,FALSE) -> 1 | I26: =IF(H26>=60%,"Cumple","No Cumple") -> Cumple | J26: =+VLOOKUP(C26,Indicadores!B:F,5,FALSE) -> 1 | K26: =IF(J26>=60%,"Cumple","No Cumple") -> Cumple | L26: =+AVERAGE(H26,J26) -> 1 | M26: =+G26*$M$3 -> 150000 | N26: =+VLOOKUP(C26,Indicadores!B:M,12,FALSE) -> 0.97777778 | O26: =IF(N26>=60%,"Cumple","No Cumple") -> Cumple | P26: =IF(N26>80%,M26*100%,IF(AND(N26>=60%,N26<=79%),M26*60%,0)) -> 150000 | Q26: =+$G$6*$Q$3 -> 50000 | R26: =+IFERROR(VLOOKUP(C26,Indicadores!B:N,13,FALSE),0%) -> 1.1133674 | S26: =IF(R26>=70%,"Cumple","No Cumple") -> Cumple | T26: =IF(R26=80%,Q26*70%,IF(AND(R26>=81%,R26<=90%),Q26*80%,IF(AND(R26>=91%,R26<=95%),Q26*90%,IF(R26=96%,Q26*96%,IF(R26=97%,Q26*97%,IF(R26=98%,Q26*98%,IF(R26=99%,Q26*99%,IF(R26>=100%,Q26,0)))))))) -> 50000 | U26: =+G26*$U$3 -> 50000 | V26: =+VLOOKUP(C26,Indicadores!B:S,18,FALSE) -> 0.5 | W26: =IF(V26>=100%,"Cumple","No Cumple") -> No Cumple | X26: =+IF(V26=100%,U26,0) -> 0 | Y26: =IF(L26>=60%,"SI","NO") -> SI | Z26: =+IF(Y26="SI",P26+T26+X26,0) -> 200000
B27: REGIONAL BOGOTA | C27: SOR_14 | D27: ALEJANDRO RODRIGUEZ | E27: ANYI MAYERLIE ORJUELA | F27: JUAN PABLO GIL ALMANZA | G27: =IF(L27>=80%,250000,IF(AND(L27>=60%,L27<80%),150000,0)) -> 250000 | H27: =+VLOOKUP(C27,Indicadores!B:C,2,FALSE) -> 1 | I27: =IF(H27>=60%,"Cumple","No Cumple") -> Cumple | J27: =+VLOOKUP(C27,Indicadores!B:F,5,FALSE) -> 1 | K27: =IF(J27>=60%,"Cumple","No Cumple") -> Cumple | L27: =+AVERAGE(H27,J27) -> 1 | M27: =+G27*$M$3 -> 150000 | N27: =+VLOOKUP(C27,Indicadores!B:M,12,FALSE) -> 1 | O27: =IF(N27>=60%,"Cumple","No Cumple") -> Cumple | P27: =IF(N27>80%,M27*100%,IF(AND(N27>=60%,N27<=79%),M27*60%,0)) -> 150000 | Q27: =+$G$6*$Q$3 -> 50000 | R27: 0.9 | S27: =IF(R27>=70%,"Cumple","No Cumple") -> Cumple | T27: =IF(R27=80%,Q27*70%,IF(AND(R27>=81%,R27<=90%),Q27*80%,IF(AND(R27>=91%,R27<=95%),Q27*90%,IF(R27=96%,Q27*96%,IF(R27=97%,Q27*97%,IF(R27>=98%,Q27*98%,IF(R27=99%,Q27*99%,IF(R27>=100%,Q27,0)))))))) -> 40000 | U27: =+G27*$U$3 -> 50000 | V27: =+VLOOKUP(C27,Indicadores!B:S,18,FALSE) -> 0.5 | W27: =IF(V27>=100%,"Cumple","No Cumple") -> No Cumple | X27: =+IF(V27=100%,U27,0) -> 0 | Y27: =IF(L27>=60%,"SI","NO") -> SI | Z27: =+IF(Y27="SI",P27+T27+X27,0) -> 190000
B28: REGIONAL BOGOTA | C28: SOR_15 | D28: ALEJANDRO RODRIGUEZ | E28: ANYI MAYERLIE ORJUELA | F28: JUAN PABLO GIL ALMANZA | G28: =IF(L28>=80%,250000,IF(AND(L28>=60%,L28<80%),150000,0)) -> 250000 | H28: =+VLOOKUP(C28,Indicadores!B:C,2,FALSE) -> 0.94444444 | I28: =IF(H28>=60%,"Cumple","No Cumple") -> Cumple | J28: =+VLOOKUP(C28,Indicadores!B:F,5,FALSE) -> 1 | K28: =IF(J28>=60%,"Cumple","No Cumple") -> Cumple | L28: =+AVERAGE(H28,J28) -> 0.97222222 | M28: =+G28*$M$3 -> 150000 | N28: =+VLOOKUP(C28,Indicadores!B:M,12,FALSE) -> 0.98148148 | O28: =IF(N28>=60%,"Cumple","No Cumple") -> Cumple | P28: =IF(N28>80%,M28*100%,IF(AND(N28>=60%,N28<=79%),M28*60%,0)) -> 150000 | Q28: =+$G$6*$Q$3 -> 50000 | R28: =+IFERROR(VLOOKUP(C28,Indicadores!B:N,13,FALSE),0%) -> 1.0407577 | S28: =IF(R28>=70%,"Cumple","No Cumple") -> Cumple | T28: =IF(R28=80%,Q28*70%,IF(AND(R28>=81%,R28<=90%),Q28*80%,IF(AND(R28>=91%,R28<=95%),Q28*90%,IF(R28=96%,Q28*96%,IF(R28=97%,Q28*97%,IF(R28=98%,Q28*98%,IF(R28=99%,Q28*99%,IF(R28>=100%,Q28,0)))))))) -> 50000 | U28: =+G28*$U$3 -> 50000 | V28: =+VLOOKUP(C28,Indicadores!B:S,18,FALSE) -> 0.97222222 | W28: =IF(V28>=100%,"Cumple","No Cumple") -> No Cumple | X28: =+IF(V28=100%,U28,0) -> 0 | Y28: =IF(L28>=60%,"SI","NO") -> SI | Z28: =+IF(Y28="SI",P28+T28+X28,0) -> 200000
B29: REGIONAL BOGOTA | C29: SOR_16 | D29: ALEJANDRO RODRIGUEZ | E29: ANYI MAYERLIE ORJUELA | F29: JUAN PABLO GIL ALMANZA | G29: =IF(L29>=80%,250000,IF(AND(L29>=60%,L29<80%),150000,0)) -> 250000 | H29: =+VLOOKUP(C29,Indicadores!B:C,2,FALSE) -> 1 | I29: =IF(H29>=60%,"Cumple","No Cumple") -> Cumple | J29: =+VLOOKUP(C29,Indicadores!B:F,5,FALSE) -> 1 | K29: =IF(J29>=60%,"Cumple","No Cumple") -> Cumple | L29: =+AVERAGE(H29,J29) -> 1 | M29: =+G29*$M$3 -> 150000 | N29: =+VLOOKUP(C29,Indicadores!B:M,12,FALSE) -> 1 | O29: =IF(N29>=60%,"Cumple","No Cumple") -> Cumple | P29: =IF(N29>80%,M29*100%,IF(AND(N29>=60%,N29<=79%),M29*60%,0)) -> 150000 | Q29: =+$G$6*$Q$3 -> 50000 | R29: =+IFERROR(VLOOKUP(C29,Indicadores!B:N,13,FALSE),0%) -> 0.98077537 | S29: =IF(R29>=70%,"Cumple","No Cumple") -> Cumple | T29: =IF(R29=80%,Q29*70%,IF(AND(R29>=81%,R29<=90%),Q29*80%,IF(AND(R29>=91%,R29<=95%),Q29*90%,IF(R29=96%,Q29*96%,IF(R29=97%,Q29*97%,IF(R29>=98%,Q29*98%,IF(R29=99%,Q29*99%,IF(R29>=100%,Q29,0)))))))) -> 49000 | U29: =+G29*$U$3 -> 50000 | V29: =+VLOOKUP(C29,Indicadores!B:S,18,FALSE) -> 1 | W29: =IF(V29>=100%,"Cumple","No Cumple") -> Cumple | X29: =+IF(V29=100%,U29,0) -> 50000 | Y29: =IF(L29>=60%,"SI","NO") -> SI | Z29: =+IF(Y29="SI",P29+T29+X29,0) -> 249000
B30: REGIONAL BOGOTA | C30: SOR_2 | D30: ALEJANDRO RODRIGUEZ | E30: ANYI MAYERLIE ORJUELA | F30: JUAN PABLO GIL ALMANZA | G30: =IF(L30>=80%,250000,IF(AND(L30>=60%,L30<80%),150000,0)) -> 250000 | H30: =+VLOOKUP(C30,Indicadores!B:C,2,FALSE) -> 1 | I30: =IF(H30>=60%,"Cumple","No Cumple") -> Cumple | J30: =+VLOOKUP(C30,Indicadores!B:F,5,FALSE) -> 1 | K30: =IF(J30>=60%,"Cumple","No Cumple") -> Cumple | L30: =+AVERAGE(H30,J30) -> 1 | M30: =+G30*$M$3 -> 150000 | N30: =+VLOOKUP(C30,Indicadores!B:M,12,FALSE) -> 1 | O30: =IF(N30>=60%,"Cumple","No Cumple") -> Cumple | P30: =IF(N30>80%,M30*100%,IF(AND(N30>=60%,N30<=79%),M30*60%,0)) -> 150000 | Q30: =+$G$6*$Q$3 -> 50000 | R30: =+IFERROR(VLOOKUP(C30,Indicadores!B:N,13,FALSE),0%) -> 0.63770592 | S30: =IF(R30>=80%,"Cumple","No Cumple") -> No Cumple | T30: =IF(R30>=70%,Q30*70%,IF(AND(R30>=81%,R30<=90%),Q30*80%,IF(AND(R30>=91%,R30<=95%),Q30*90%,IF(R30=96%,Q30*96%,IF(R30=97%,Q30*97%,IF(R30=98%,Q30*98%,IF(R30=99%,Q30*99%,IF(R30>=100%,Q30,0)))))))) -> 0 | U30: =+G30*$U$3 -> 50000 | V30: =+VLOOKUP(C30,Indicadores!B:S,18,FALSE) -> 0.5 | W30: =IF(V30>=100%,"Cumple","No Cumple") -> No Cumple | X30: =+IF(V30=100%,U30,0) -> 0 | Y30: =IF(L30>=60%,"SI","NO") -> SI | Z30: =+IF(Y30="SI",P30+T30+X30,0) -> 150000
B31: REGIONAL BOGOTA | C31: SOR_3 | D31: ALEJANDRO RODRIGUEZ | E31: ANYI MAYERLIE ORJUELA | F31: JUAN PABLO GIL ALMANZA | G31: =IF(L31>=80%,250000,IF(AND(L31>=60%,L31<80%),150000,0)) -> 250000 | H31: =+VLOOKUP(C31,Indicadores!B:C,2,FALSE) -> 1 | I31: =IF(H31>=60%,"Cumple","No Cumple") -> Cumple | J31: =+VLOOKUP(C31,Indicadores!B:F,5,FALSE) -> 1 | K31: =IF(J31>=60%,"Cumple","No Cumple") -> Cumple | L31: =+AVERAGE(H31,J31) -> 1 | M31: =+G31*$M$3 -> 150000 | N31: =+VLOOKUP(C31,Indicadores!B:M,12,FALSE) -> 1 | O31: =IF(N31>=60%,"Cumple","No Cumple") -> Cumple | P31: =IF(N31>80%,M31*100%,IF(AND(N31>=60%,N31<=79%),M31*60%,0)) -> 150000 | Q31: =+$G$6*$Q$3 -> 50000 | R31: =+IFERROR(VLOOKUP(C31,Indicadores!B:N,13,FALSE),0%) -> 0.92267607 | S31: =IF(R31>=70%,"Cumple","No Cumple") -> Cumple | T31: =IF(R31=80%,Q31*70%,IF(AND(R31>=81%,R31<=90%),Q31*80%,IF(AND(R31>=91%,R31<=95%),Q31*90%,IF(R31=96%,Q31*96%,IF(R31=97%,Q31*97%,IF(R31=98%,Q31*98%,IF(R31=99%,Q31*99%,IF(R31>=100%,Q31,0)))))))) -> 45000 | U31: =+G31*$U$3 -> 50000 | V31: =+VLOOKUP(C31,Indicadores!B:S,18,FALSE) -> 1 | W31: =IF(V31>=100%,"Cumple","No Cumple") -> Cumple | X31: =+IF(V31=100%,U31,0) -> 50000 | Y31: =IF(L31>=60%,"SI","NO") -> SI | Z31: =+IF(Y31="SI",P31+T31+X31,0) -> 245000
B32: REGIONAL BOGOTA | C32: SOR_4 | D32: ALEJANDRO RODRIGUEZ | E32: ANYI MAYERLIE ORJUELA | F32: JUAN PABLO GIL ALMANZA | G32: =IF(L32>=80%,250000,IF(AND(L32>=60%,L32<80%),150000,0)) -> 250000 | H32: =+VLOOKUP(C32,Indicadores!B:C,2,FALSE) -> 1 | I32: =IF(H32>=60%,"Cumple","No Cumple") -> Cumple | J32: =+VLOOKUP(C32,Indicadores!B:F,5,FALSE) -> 1 | K32: =IF(J32>=60%,"Cumple","No Cumple") -> Cumple | L32: =+AVERAGE(H32,J32) -> 1 | M32: =+G32*$M$3 -> 150000 | N32: =+VLOOKUP(C32,Indicadores!B:M,12,FALSE) -> 1 | O32: =IF(N32>=60%,"Cumple","No Cumple") -> Cumple | P32: =IF(N32>80%,M32*100%,IF(AND(N32>=60%,N32<=79%),M32*60%,0)) -> 150000 | Q32: =+$G$6*$Q$3 -> 50000 | R32: =+IFERROR(VLOOKUP(C32,Indicadores!B:N,13,FALSE),0%) -> 1.0741337 | S32: =IF(R32>=70%,"Cumple","No Cumple") -> Cumple | T32: =IF(R32=80%,Q32*70%,IF(AND(R32>=81%,R32<=90%),Q32*80%,IF(AND(R32>=91%,R32<=95%),Q32*90%,IF(R32=96%,Q32*96%,IF(R32=97%,Q32*97%,IF(R32=98%,Q32*98%,IF(R32=99%,Q32*99%,IF(R32>=100%,Q32,0)))))))) -> 50000 | U32: =+G32*$U$3 -> 50000 | V32: =+VLOOKUP(C32,Indicadores!B:S,18,FALSE) -> 1 | W32: =IF(V32>=100%,"Cumple","No Cumple") -> Cumple | X32: =+IF(V32=100%,U32,0) -> 50000 | Y32: =IF(L32>=60%,"SI","NO") -> SI | Z32: =+IF(Y32="SI",P32+T32+X32,0) -> 250000
B33: REGIONAL BOGOTA | C33: SOR_5 | D33: ALEJANDRO RODRIGUEZ | E33: ANYI MAYERLIE ORJUELA | F33: JUAN PABLO GIL ALMANZA | G33: =IF(L33>=80%,250000,IF(AND(L33>=60%,L33<80%),150000,0)) -> 250000 | H33: =+VLOOKUP(C33,Indicadores!B:C,2,FALSE) -> 1 | I33: =IF(H33>=60%,"Cumple","No Cumple") -> Cumple | J33: =+VLOOKUP(C33,Indicadores!B:F,5,FALSE) -> 1 | K33: =IF(J33>=60%,"Cumple","No Cumple") -> Cumple | L33: =+AVERAGE(H33,J33) -> 1 | M33: =+G33*$M$3 -> 150000 | N33: =+VLOOKUP(C33,Indicadores!B:M,12,FALSE) -> 1 | O33: =IF(N33>=60%,"Cumple","No Cumple") -> Cumple | P33: =IF(N33>80%,M33*100%,IF(AND(N33>=60%,N33<=79%),M33*60%,0)) -> 150000 | Q33: =+$G$6*$Q$3 -> 50000 | R33: =+IFERROR(VLOOKUP(C33,Indicadores!B:N,13,FALSE),0%) -> 1.114458 | S33: =IF(R33>=70%,"Cumple","No Cumple") -> Cumple | T33: =IF(R33=80%,Q33*70%,IF(AND(R33>=81%,R33<=90%),Q33*80%,IF(AND(R33>=91%,R33<=95%),Q33*90%,IF(R33=96%,Q33*96%,IF(R33=97%,Q33*97%,IF(R33=98%,Q33*98%,IF(R33=99%,Q33*99%,IF(R33>=100%,Q33,0)))))))) -> 50000 | U33: =+G33*$U$3 -> 50000 | V33: =+VLOOKUP(C33,Indicadores!B:S,18,FALSE) -> 1 | W33: =IF(V33>=100%,"Cumple","No Cumple") -> Cumple | X33: =+IF(V33=100%,U33,0) -> 50000 | Y33: =IF(L33>=60%,"SI","NO") -> SI | Z33: =+IF(Y33="SI",P33+T33+X33,0) -> 250000
B34: REGIONAL BOGOTA | C34: SOR_6 | D34: ALEJANDRO RODRIGUEZ | E34: ANYI MAYERLIE ORJUELA | F34: JUAN PABLO GIL ALMANZA | G34: =IF(L34>=80%,250000,IF(AND(L34>=60%,L34<80%),150000,0)) -> 250000 | H34: =+VLOOKUP(C34,Indicadores!B:C,2,FALSE) -> 1 | I34: =IF(H34>=60%,"Cumple","No Cumple") -> Cumple | J34: =+VLOOKUP(C34,Indicadores!B:F,5,FALSE) -> 1 | K34: =IF(J34>=60%,"Cumple","No Cumple") -> Cumple | L34: =+AVERAGE(H34,J34) -> 1 | M34: =+G34*$M$3 -> 150000 | N34: =+VLOOKUP(C34,Indicadores!B:M,12,FALSE) -> 1 | O34: =IF(N34>=60%,"Cumple","No Cumple") -> Cumple | P34: =IF(N34>80%,M34*100%,IF(AND(N34>=60%,N34<=79%),M34*60%,0)) -> 150000 | Q34: =+$G$6*$Q$3 -> 50000 | R34: =+IFERROR(VLOOKUP(C34,Indicadores!B:N,13,FALSE),0%) -> 0.97915641 | S34: =IF(R34>=70%,"Cumple","No Cumple") -> Cumple | T34: =IF(R34=80%,Q34*70%,IF(AND(R34>=81%,R34<=90%),Q34*80%,IF(AND(R34>=91%,R34<=95%),Q34*90%,IF(R34=96%,Q34*96%,IF(R34>=97%,Q34*97%,IF(R34>=98%,Q34*98%,IF(R34=99%,Q34*99%,IF(R34>=100%,Q34,0)))))))) -> 48500 | U34: =+G34*$U$3 -> 50000 | V34: =+VLOOKUP(C34,Indicadores!B:S,18,FALSE) -> 1 | W34: =IF(V34>=100%,"Cumple","No Cumple") -> Cumple | X34: =+IF(V34=100%,U34,0) -> 50000 | Y34: =IF(L34>=60%,"SI","NO") -> SI | Z34: =+IF(Y34="SI",P34+T34+X34,0) -> 248500
B35: REGIONAL BOGOTA | C35: SOR_7 | D35: ALEJANDRO RODRIGUEZ | E35: ANYI MAYERLIE ORJUELA | F35: JUAN PABLO GIL ALMANZA | G35: =IF(L35>=80%,250000,IF(AND(L35>=60%,L35<80%),150000,0)) -> 250000 | H35: =+VLOOKUP(C35,Indicadores!B:C,2,FALSE) -> 1 | I35: =IF(H35>=60%,"Cumple","No Cumple") -> Cumple | J35: =+VLOOKUP(C35,Indicadores!B:F,5,FALSE) -> 1 | K35: =IF(J35>=60%,"Cumple","No Cumple") -> Cumple | L35: =+AVERAGE(H35,J35) -> 1 | M35: =+G35*$M$3 -> 150000 | N35: =+VLOOKUP(C35,Indicadores!B:M,12,FALSE) -> 1 | O35: =IF(N35>=60%,"Cumple","No Cumple") -> Cumple | P35: =IF(N35>80%,M35*100%,IF(AND(N35>=60%,N35<=79%),M35*60%,0)) -> 150000 | Q35: =+$G$6*$Q$3 -> 50000 | R35: =+IFERROR(VLOOKUP(C35,Indicadores!B:N,13,FALSE),0%) -> 1.0518477 | S35: =IF(R35>=70%,"Cumple","No Cumple") -> Cumple | T35: =IF(R35=80%,Q35*70%,IF(AND(R35>=81%,R35<=90%),Q35*80%,IF(AND(R35>=91%,R35<=95%),Q35*90%,IF(R35=96%,Q35*96%,IF(R35=97%,Q35*97%,IF(R35=98%,Q35*98%,IF(R35=99%,Q35*99%,IF(R35>=100%,Q35,0)))))))) -> 50000 | U35: =+G35*$U$3 -> 50000 | V35: =+VLOOKUP(C35,Indicadores!B:S,18,FALSE) -> 0.5 | W35: =IF(V35>=100%,"Cumple","No Cumple") -> No Cumple | X35: =+IF(V35=100%,U35,0) -> 0 | Y35: =IF(L35>=60%,"SI","NO") -> SI | Z35: =+IF(Y35="SI",P35+T35+X35,0) -> 200000
