Workbook

Sheet Liquidacion Lideres y Superviso
A1: MES | B1: CARGO | C1: NOMBRE | D1: LLAVE 1 CAPTURA | E1: LLAVE 2 COBERTURA | F1: PROM. LLAVE | G1: VALOR COMISION TP | H1: % CUMPL. TP | I1: VALOR COMISION | J1: VALOR COMISION VENTAS | K1: % VENTAS | L1: VALOR COMISION | M1: VALOR COMISION X FC DV | N1: % FC & DV | O1: VALOR COMISION | P1: Valor Comision | Q1: Valor a Pagar | R1: Comentario | S1: Cumple Llaves
A2: JULIO | B2: LIDER | C2: ANYI MAYERLIE ORJUELA | D2: 0.79407662 | E2: 0.96165107 | F2: 0.87786385 | G2: 240000 | H2: 0.5909551 | I2: 141829.22 | J2: 80000 | K2: 0.95 | L2: 76000 | M2: 80000 | N2: 0.85826224 | O2: 64000 | P2: 400000 | Q2: 281829.22 | S2: SI
A3: JULIO | B3: LIDER | C3: HECTOR MEDINA ROZO | D3: 0.73291655 | E3: 0.90862361 | F3: 0.82077008 | G3: 240000 | H3: 0.454592 | I3: 0 | J3: 80000 | K3: 0.95 | L3: 76000 | M3: 80000 | N3: 0.741079 | O3: 0 | P3: 400000 | Q3: 76000 | S3: SI
A4: JULIO | B4: LIDER | C4: MONICA GIRALDO HERNANDEZ | D4: 0.7842858 | E4: 0.94727881 | F4: 0.86578231 | G4: 240000 | H4: 0.57371461 | I4: 137691.51 | J4: 80000 | K4: 0.95 | L4: 76000 | M4: 80000 | N4: 0.66103539 | O4: 0 | P4: 400000 | Q4: 213691.51 | S4: SI
A5: JULIO | B5: SUPERVISOR | C5: GIL MARTINEZ JENNIFER STEFANNIE | D5: 0.72796919 | E5: 0.82167566 | F5: 0.77482242 | G5: 180000 | H5: 0.42404444 | I5: 0 | J5: 60000 | K5: 0.95 | L5: 57000 | M5: 60000 | N5: 0.61175278 | O5: 0 | P5: 300000 | Q5: 57000 | S5: SI
A6: JULIO | B6: SUPERVISOR | C6: MELISA MARTINEZ | D6: 0.72651394 | E6: 0.99238095 | F6: 0.85944745 | G6: 180000 | H6: 0.4916 | I6: 0 | J6: 60000 | K6: 0.95 | L6: 57000 | M6: 60000 | N6: 0.62542667 | O6: 0 | P6: 300000 | Q6: 57000 | S6: SI
A7: JULIO | B7: SUPERVISOR | C7: SUSANA SILVA MENDOZA | D7: 0.74428961 | E7: 0.90707877 | F7: 0.82568419 | G7: 180000 | H7: 0.47044762 | I7: 0 | J7: 60000 | K7: 0.95 | L7: 57000 | M7: 60000 | N7: 0.65495714 | O7: 0 | P7: 300000 | Q7: 57000 | S7: SI
A8: JULIO | B8: SUPERVISOR | C8: JUAN PABLO GIL ALMANZA | D8: 0.82545 | E8: 0.9875 | F8: 0.906475 | G8: 180000 | H8: 0.66263958 | I8: 119275.13 | J8: 60000 | K8: 0.95 | L8: 57000 | M8: 60000 | N8: 0.97 | O8: 58200 | P8: 300000 | Q8: 234475.12 | S8: SI
A9: JULIO | B9: SUPERVISOR | C9: PIÑEROS MONTAÑA LAURA ESTEPHANIA | D9: 0.80434211 | E9: 0.98009471 | F9: 0.89221841 | G9: 180000 | H9: 0.61938421 | I9: 111489.16 | J9: 60000 | K9: 0.95 | L9: 57000 | M9: 60000 | N9: 0.91566579 | O9: 54000 | P9: 300000 | Q9: 222489.16 | S9: SI
A10: JULIO | B10: SUPERVISOR | C10: MEJÍA BLANDÓN ASTRID KARINA | D10: 0.79483117 | E10: 0.97283452 | F10: 0.88383284 | G10: 180000 | H10: 0.56215238 | I10: 101187.43 | J10: 60000 | K10: 0.95 | L10: 57000 | M10: 60000 | N10: 0.64117857 | O10: 0 | P10: 300000 | Q10: 158187.43 | S10: SI
A11: JULIO | B11: SUPERVISOR | C11: PEREZ ZAGARRA AUGUSTO EDUARDO | D11: 0.81263967 | E11: 0.96685863 | F11: 0.88974915 | G11: 180000 | H11: 0.56086061 | I11: 100954.91 | J11: 60000 | K11: 0.95 | L11: 57000 | M11: 60000 | N11: 0.58981364 | O11: 0 | P11: 300000 | Q11: 157954.91 | S11: SI
A12: JULIO | B12: SUPERVISOR | C12: GONZALEZ BARRANTES EDWIN JESSID | D12: 0.74380428 | E12: 0.9267826 | F12: 0.83529344 | G12: 180000 | H12: 0.45428235 | I12: 0 | J12: 60000 | K12: 0.95 | L12: 57000 | M12: 60000 | N12: 0.98 | O12: 58800 | P12: 300000 | Q12: 115800 | S12: SI
A13: JULIO | B13: SUPERVISOR | C13: CAMPUZANO IRLET ANDREA | D13: 0.76249545 | E13: 0.94038872 | F13: 0.85144209 | G13: 180000 | H13: 0.65167667 | I13: 117301.8 | J13: 60000 | K13: 0.95 | L13: 57000 | M13: 60000 | N13: 0.57183 | O13: 0 | P13: 300000 | Q13: 174301.8 | S13: SI
... A17: JULIO | B17: SUPERVISOR | C17: OSSA TABARES JAZMIN BERNARDA | D17: 0.77788347 | E17: 0.92766106 | F17: 0.85277227 | G17: 180000 | H17: 0.61910909 | I17: 111439.64 | J17: 60000 | K17: 0.95 | L17: 57000 | M17: 60000 | N17: 0.48893636 | O17: 0 | P17: 300000 | Q17: 168439.64 | S17: SI
G18: TIENDA PERFECTA | J18: VENTAS | M18: FECHAS CORTAS Y DEVOLUCIONES | Q18: TOTAL LIQUIDAR

Sheet TD Supervisores Y Lideres Prom
B2: SUPERVISORES
B3: COORDINADOR | C3: % Cumplimiento TP | D3: % Cumplimiento Ventas | E3: % Cumplimiento FC & DV | F3: Valor Comision
B4: GIL MARTINEZ JENNIFER STEFANNIE | C4: 0.42404444 | D4: 0.95 | E4: 0.61175278 | F4: 300000
B5: MELISA MARTINEZ | C5: 0.4916 | D5: 0.95 | E5: 0.62542667 | F5: 300000
B6: SUSANA SILVA MENDOZA | C6: 0.47044762 | D6: 0.95 | E6: 0.65495714 | F6: 300000
B7: JUAN PABLO GIL ALMANZA | C7: 0.66263958 | D7: 0.95 | E7: 0.9679875 | F7: 300000
B8: PIÑEROS MONTAÑA LAURA ESTEPHANIA | C8: 0.61938421 | D8: 0.95 | E8: 0.91566579 | F8: 300000
B9: MEJÍA BLANDÓN ASTRID KARINA | C9: 0.56215238 | D9: 0.95 | E9: 0.64117857 | F9: 300000
B10: PEREZ ZAGARRA AUGUSTO EDUARDO | C10: 0.56086061 | D10: 0.95 | E10: 0.58981364 | F10: 300000
B11: GONZALEZ BARRANTES EDWIN JESSID | C11: 0.45428235 | D11: 0.95 | E11: 0.98005882 | F11: 300000
B12: CAMPUZANO IRLET ANDREA | C12: 0.65167667 | D12: 0.95 | E12: 0.57183 | F12: 300000
B13: ROSERO JURADO LAURA CATALINA | C13: 0.40322308 | D13: 0.95 | E13: 0.80693462 | F13: 300000
B14: SÁNCHEZ ZAMBRANO LEIDY NICOLE VANESSA | C14: 0.63954902 | D14: 0.95 | E14: 0.7329 | F14: 300000
B15: ARIAS GARCÍA MARIAN JULIE | C15: 0.58306154 | D15: 0.95 | E15: 0.71705 | F15: 300000
B16: OSSA TABARES JAZMIN BERNARDA | C16: 0.61910909 | D16: 0.95 | E16: 0.48893636 | F16: 300000
B17: Total general | C17: 0.5465266 | D17: 0.95 | E17: 0.73372846 | F17: =+SUM(F4:F16) -> 3900000
B19: LIDERES
B20: COORDINADOR | C20: Promedio de % Cumplimiento TP | D20: Promedio de % Cumplimiento Ventas | E20: Promedio de % Cumplimiento FC & DV | F20: Valor Comision
B21: ANYI MAYERLIE ORJUELA | C21: 0.5909551 | D21: 0.95 | E21: 0.85826224 | F21: 400000
B22: HECTOR MEDINA ROZO | C22: 0.454592 | D22: 0.95 | E22: 0.741079 | F22: 400000
B23: MONICA GIRALDO HERNANDEZ | C23: 0.57371461 | D23: 0.95 | E23: 0.66103539 | F23: 400000
B24: Total general | C24: 0.5465266 | D24: 0.95 | E24: 0.73372846
B26: SUPERVISORES
B27: COORDINADOR | C27: Promedio de % Cumpl. Captura | D27: Promedio de % Cumplimiento Cobertura
B28: GIL MARTINEZ JENNIFER STEFANNIE | C28: 0.72796919 | D28: 0.82167566
B29: MELISA MARTINEZ | C29: 0.72651394 | D29: 0.99238095
B30: SUSANA SILVA MENDOZA | C30: 0.74428961 | D30: 0.90707877
B31: JUAN PABLO GIL ALMANZA | C31: 0.82545 | D31: 0.9875
B32: PIÑEROS MONTAÑA LAURA ESTEPHANIA | C32: 0.80434211 | D32: 0.98009471
B33: MEJÍA BLANDÓN ASTRID KARINA | C33: 0.79483117 | D33: 0.97283452
B34: PEREZ ZAGARRA AUGUSTO EDUARDO | C34: 0.81263967 | D34: 0.96685863
B35: GONZALEZ BARRANTES EDWIN JESSID | C35: 0.74380428 | D35: 0.9267826
B36: CAMPUZANO IRLET ANDREA | C36: 0.76249545 | D36: 0.94038872
B37: ROSERO JURADO LAURA CATALINA | C37: 0.74805035 | D37: 0.90092045
B38: SÁNCHEZ ZAMBRANO LEIDY NICOLE VANESSA | C38: 0.78396417 | D38: 0.9710585
B39: ARIAS GARCÍA MARIAN JULIE | C39: 0.80777273 | D39: 0.94035132
... B41: Total general | C41: 0.77317563 | D41: 0.94074413
B43: SUPERVISORES
B44: COORDINADOR | C44: Promedio de % Cumpl. Captura | D44: Promedio de % Cumplimiento Cobertura
B45: ANYI MAYERLIE ORJUELA | C45: 0.79407662 | D45: 0.96165107
...

Sheet Liq. Mercaderista 1ra Llave 95%
W1: SI | X1: =+COUNTIF(W6:W193,W1) -> 0
B2: LLAVE DEL 95% | W2: Equipo ganador | X2: =+X1/188 -> 0
G3: LLAVE | I3: LLAVE | K3: 0.6 | O3: 0.2 | S3: 0.2
F4: 250000 | G4: CAPTURA DE INFORMACION | K4: TIENDA PERFECTA | O4: VENTAS | S4: DEVOLUCIONES & FECHAS CORTAS | X4: =+SUBTOTAL(9,X6:X193) -> 0
B5: Regional | C5: RUTA | D5: Lider | E5: Supervisor | F5: Valor Comision | G5: % Cumpl. Captura | H5: Categoria Efec 95% | I5: % Cumplimiento Cobertura | J5: Categoria Efec 95% | K5: Valor Comision TP | L5: % Cumplimiento TP | M5: Categoria Efec >80% | N5: $ Liquidar | O5: Valor Comision Ventas | P5: % Cumplimiento Ventas | Q5: Categoria Efec | R5: $ Liquidar | S5: Valor Comision FC y Dev | T5: % Cumplimiento FC & DV | U5: Categoria Efec | V5: $ Liquidar | W5: Corresponde Comision | X5: Valor total A Pagar Real | Y5: Observaciones
B6: REGIONAL BOGOTA | C6: CTR_1 | D6: ANYI MAYERLIE ORJUELA | E6: SUSANA SILVA MENDOZA | F6: =+$F$4 -> 250000 | G6: =+VLOOKUP(C6,Indicadores!B:C,2,FALSE) -> 0.8841 | H6: =IF(G6>=95%,"Cumple","No Cumple") -> No Cumple | I6: =+VLOOKUP(C6,Indicadores!B:F,5,FALSE) -> 1 | J6: =IF(I6>=95%,"Cumple","No Cumple") -> Cumple | K6: =+$F$4*$K$3 -> 150000 | L6: =+VLOOKUP(C6,Indicadores!B:P,15,FALSE) -> 0.86933333 | M6: =IF(L6>=80%,"Cumple","No Cumple") -> Cumple | N6: =IF(L6=80%,K6*70%,IF(AND(L6>=81%,L6<=90%),K6*80%,IF(AND(L6>=91%,L6<=95%),K6*90%,IF(L6=96%,K6*96%,IF(L6=97%,K6*97%,IF(L6=98%,K6*98%,IF(L6=99%,K6*99%,IF(L6=100%,K6,0)))))))) -> 120000 | O6: =+$F$4*$O$3 -> 50000 | P6: 0.95 | Q6: =IF(P6>=80%,"Cumple","No Cumple") -> Cumple | R6: =+O6*95% -> 47500 | S6: =+$F$4*$S$3 -> 50000 | T6: =+VLOOKUP(C6,Indicadores!B:V,21,FALSE) -> 0.489 | U6: =IF(T6>=100%,"Cumple","No Cumple") -> No Cumple | V6: =IF(T6=100%,S6,0) -> 0 | W6: =IF(AND(G6>=95%,I6>=95%),"SI","NO") -> NO | X6: =+IF(W6="SI",N6+R6+V6,0) -> 0
B7: REGIONAL BOGOTA | C7: CTR_10 | D7: ANYI MAYERLIE ORJUELA | E7: SUSANA SILVA MENDOZA | F7: =+$F$4 -> 250000 | G7: =+VLOOKUP(C7,Indicadores!B:C,2,FALSE) -> 0.7519 | H7: =IF(G7>=95%,"Cumple","No Cumple") -> No Cumple | I7: =+VLOOKUP(C7,Indicadores!B:F,5,FALSE) -> 1 | J7: =IF(I7>=95%,"Cumple","No Cumple") -> Cumple | K7: =+$F$4*$K$3 -> 150000 | L7: =+VLOOKUP(C7,Indicadores!B:P,15,FALSE) -> 0.40476667 | M7: =IF(L7>=80%,"Cumple","No Cumple") -> No Cumple | N7: =IF(L7=80%,K7*70%,IF(AND(L7>=81%,L7<=90%),K7*80%,IF(AND(L7>=91%,L7<=95%),K7*90%,IF(L7=96%,K7*96%,IF(L7=97%,K7*97%,IF(L7=98%,K7*98%,IF(L7=99%,K7*99%,IF(L7=100%,K7,0)))))))) -> 0 | O7: =+$F$4*$O$3 -> 50000 | P7: 0.95 | Q7: =IF(P7>=80%,"Cumple","No Cumple") -> Cumple | R7: =+O7*95% -> 47500 | S7: =+$F$4*$S$3 -> 50000 | T7: =+VLOOKUP(C7,Indicadores!B:V,21,FALSE) -> 1 | U7: =IF(T7>=100%,"Cumple","No Cumple") -> Cumple | V7: =IF(T7=100%,S7,0) -> 50000 | W7: =IF(AND(G7>=95%,I7>=95%),"SI","NO") -> NO | X7: =+IF(W7="SI",N7+R7+V7,0) -> 0
B8: REGIONAL BOGOTA | C8: CTR_11 | D8: ANYI MAYERLIE ORJUELA | E8: SUSANA SILVA MENDOZA | F8: =+$F$4 -> 250000 | G8: =+VLOOKUP(C8,Indicadores!B:C,2,FALSE) -> 0.75821818 | H8: =IF(G8>=95%,"Cumple","No Cumple") -> No Cumple | I8: =+VLOOKUP(C8,Indicadores!B:F,5,FALSE) -> 0.44444444 | J8: =IF(I8>=95%,"Cumple","No Cumple") -> No Cumple | K8: =+$F$4*$K$3 -> 150000 | L8: =+VLOOKUP(C8,Indicadores!B:P,15,FALSE) -> 0.39656667 | M8: =IF(L8>=80%,"Cumple","No Cumple") -> No Cumple | N8: =IF(L8=80%,K8*70%,IF(AND(L8>=81%,L8<=90%),K8*80%,IF(AND(L8>=91%,L8<=95%),K8*90%,IF(L8=96%,K8*96%,IF(L8=97%,K8*97%,IF(L8=98%,K8*98%,IF(L8=99%,K8*99%,IF(L8=100%,K8,0)))))))) -> 0 | O8: =+$F$4*$O$3 -> 50000 | P8: 0.95 | Q8: =IF(P8>=80%,"Cumple","No Cumple") -> Cumple | R8: =+O8*95% -> 47500 | S8: =+$F$4*$S$3 -> 50000 | T8: =+VLOOKUP(C8,Indicadores!B:V,21,FALSE) -> 0.48935 | U8: =IF(T8>=100%,"Cumple","No Cumple") -> No Cumple | V8: =IF(T8=100%,S8,0) -> 0 | W8: =IF(AND(G8>=95%,I8>=95%),"SI","NO") -> NO | X8: =+IF(W8="SI",N8+R8+V8,0) -> 0
B9: REGIONAL BOGOTA | C9: CTR_12 | D9: ANYI MAYERLIE ORJUELA | E9: SUSANA SILVA MENDOZA | F9: =+$F$4 -> 250000 | G9: =+VLOOKUP(C9,Indicadores!B:C,2,FALSE) -> 0.70937273 | H9: =IF(G9>=95%,"Cumple","No Cumple") -> No Cumple | I9: =+VLOOKUP(C9,Indicadores!B:F,5,FALSE) -> 0.82608696 | J9: =IF(I9>=95%,"Cumple","No Cumple") -> No Cumple | K9: =+$F$4*$K$3 -> 150000 | L9: =+VLOOKUP(C9,Indicadores!B:P,15,FALSE) -> 0.35353333 | M9: =IF(L9>=80%,"Cumple","No Cumple") -> No Cumple | N9: =IF(L9=80%,K9*70%,IF(AND(L9>=81%,L9<=90%),K9*80%,IF(AND(L9>=91%,L9<=95%),K9*90%,IF(L9=96%,K9*96%,IF(L9=97%,K9*97%,IF(L9=98%,K9*98%,IF(L9=99%,K9*99%,IF(L9=100%,K9,0)))))))) -> 0 | O9: =+$F$4*$O$3 -> 50000 | P9: 0.95 | Q9: =IF(P9>=80%,"Cumple","No Cumple") -> Cumple | R9: =+O9*95% -> 47500 | S9: =+$F$4*$S$3 -> 50000 | T9: =+VLOOKUP(C9,Indicadores!B:V,21,FALSE) -> 0.4697 | U9: =IF(T9>=100%,"Cumple","No Cumple") -> No Cumple | V9: =IF(T9=100%,S9,0) -> 0 | W9: =IF(AND(G9>=95%,I9>=95%),"SI","NO") -> NO | X9: =+IF(W9="SI",N9+R9+V9,0) -> 0
B10: REGIONAL BOGOTA | C10: CTR_13 | D10: ANYI MAYERLIE ORJUELA | E10: SUSANA SILVA MENDOZA | F10: =+$F$4 -> 250000 | G10: =+VLOOKUP(C10,Indicadores!B:C,2,FALSE) -> 0.75084545 | H10: =IF(G10>=95%,"Cumple","No Cumple") -> No Cumple | I10: =+VLOOKUP(C10,Indicadores!B:F,5,FALSE) -> 1 | J10: =IF(I10>=95%,"Cumple","No Cumple") -> Cumple | K10: =+$F$4*$K$3 -> 150000 | L10: =+VLOOKUP(C10,Indicadores!B:P,15,FALSE) -> 0.53333333 | M10: =IF(L10>=80%,"Cumple","No Cumple") -> No Cumple | N10: =IF(L10=80%,K10*70%,IF(AND(L10>=81%,L10<=90%),K10*80%,IF(AND(L10>=91%,L10<=95%),K10*90%,IF(L10=96%,K10*96%,IF(L10=97%,K10*97%,IF(L10=98%,K10*98%,IF(L10=99%,K10*99%,IF(L10=100%,K10,0)))))))) -> 0 | O10: =+$F$4*$O$3 -> 50000 | P10: 0.95 | Q10: =IF(P10>=80%,"Cumple","No Cumple") -> Cumple | R10: =+O10*95% -> 47500 | S10: =+$F$4*$S$3 -> 50000 | T10: =+VLOOKUP(C10,Indicadores!B:V,21,FALSE) -> 1 | U10: =IF(T10>=100%,"Cumple","No Cumple") -> Cumple | V10: =IF(T10=100%,S10,0) -> 50000 | W10: =IF(AND(G10>=95%,I10>=95%),"SI","NO") -> NO | X10: =+IF(W10="SI",N10+R10+V10,0) -> 0
B11: REGIONAL BOGOTA | C11: CTR_14 | D11: ANYI MAYERLIE ORJUELA | E11: SUSANA SILVA MENDOZA | F11: =+$F$4 -> 250000 | G11: =+VLOOKUP(C11,Indicadores!B:C,2,FALSE) -> 0.4869 | H11: =IF(G11>=95%,"Cumple","No Cumple") -> No Cumple | I11: =+VLOOKUP(C11,Indicadores!B:F,5,FALSE) -> 1 | J11: =IF(I11>=95%,"Cumple","No Cumple") -> Cumple | K11: =+$F$4*$K$3 -> 150000 | L11: =+VLOOKUP(C11,Indicadores!B:P,15,FALSE) -> 0.30066667 | M11: =IF(L11>=80%,"Cumple","No Cumple") -> No Cumple | N11: =IF(L11=80%,K11*70%,IF(AND(L11>=81%,L11<=90%),K11*80%,IF(AND(L11>=91%,L11<=95%),K11*90%,IF(L11=96%,K11*96%,IF(L11=97%,K11*97%,IF(L11=98%,K11*98%,IF(L11=99%,K11*99%,IF(L11=100%,K11,0)))))))) -> 0 | O11: =+$F$4*$O$3 -> 50000 | P11: 0.95 | Q11: =IF(P11>=80%,"Cumple","No Cumple") -> Cumple | R11: =+O11*95% -> 47500 | S11: =+$F$4*$S$3 -> 50000 | T11: =+VLOOKUP(C11,Indicadores!B:V,21,FALSE) -> 0.38985 | U11: =IF(T11>=100%,"Cumple","No Cumple") -> No Cumple | V11: =IF(T11=100%,S11,0) -> 0 | W11: =IF(AND(G11>=95%,I11>=95%),"SI","NO") -> NO | X11: =+IF(W11="SI",N11+R11+V11,0) -> 0
B12: REGIONAL BOGOTA | C12: CTR_15 | D12: ANYI MAYERLIE ORJUELA | E12: SUSANA SILVA MENDOZA | F12: =+$F$4 -> 250000 | G12: =+VLOOKUP(C12,Indicadores!B:C,2,FALSE) -> 0.78221818 | H12: =IF(G12>=95%,"Cumple","No Cumple") -> No Cumple | I12: =+VLOOKUP(C12,Indicadores!B:F,5,FALSE) -> 1 | J12: =IF(I12>=95%,"Cumple","No Cumple") -> Cumple | K12: =+$F$4*$K$3 -> 150000 | L12: =+VLOOKUP(C12,Indicadores!B:P,15,FALSE) -> 0.56656667 | M12: =IF(L12>=80%,"Cumple","No Cumple") -> No Cumple | N12: =IF(L12=80%,K12*70%,IF(AND(L12>=81%,L12<=90%),K12*80%,IF(AND(L12>=91%,L12<=95%),K12*90%,IF(L12=96%,K12*96%,IF(L12=97%,K12*97%,IF(L12=98%,K12*98%,IF(L12=99%,K12*99%,IF(L12=100%,K12,0)))))))) -> 0 | O12: =+$F$4*$O$3 -> 50000 | P12: 0.95 | Q12: =IF(P12>=80%,"Cumple","No Cumple") -> Cumple | R12: =+O12*95% -> 47500 | S12: =+$F$4*$S$3 -> 50000 | T12: =+VLOOKUP(C12,Indicadores!B:V,21,FALSE) -> 0.4945 | U12: =IF(T12>=100%,"Cumple","No Cumple") -> No Cumple | V12: =IF(T12=100%,S12,0) -> 0 | W12: =IF(AND(G12>=95%,I12>=95%),"SI","NO") -> NO | X12: =+IF(W12="SI",N12+R12+V12,0) -> 0
B13: REGIONAL BOGOTA | C13: CTR_16 | D13: ANYI MAYERLIE ORJUELA | E13: SUSANA SILVA MENDOZA | F13: =+$F$4 -> 250000 | G13: =+VLOOKUP(C13,Indicadores!B:C,2,FALSE) -> 0.7544 | H13: =IF(G13>=95%,"Cumple","No Cumple") -> No Cumple | I13: =+VLOOKUP(C13,Indicadores!B:F,5,FALSE) -> 0.92857143 | J13: =IF(I13>=95%,"Cumple","No Cumple") -> No Cumple | K13: =+$F$4*$K$3 -> 150000 | L13: =+VLOOKUP(C13,Indicadores!B:P,15,FALSE) -> 0.369 | M13: =IF(L13>=80%,"Cumple","No Cumple") -> No Cumple | N13: =IF(L13=80%,K13*70%,IF(AND(L13>=81%,L13<=90%),K13*80%,IF(AND(L13>=91%,L13<=95%),K13*90%,IF(L13=96%,K13*96%,IF(L13=97%,K13*97%,IF(L13=98%,K13*98%,IF(L13=99%,K13*99%,IF(L13=100%,K13,0)))))))) -> 0 | O13: =+$F$4*$O$3 -> 50000 | P13: 0.95 | Q13: =IF(P13>=80%,"Cumple","No Cumple") -> Cumple | R13: =+O13*95% -> 47500 | S13: =+$F$4*$S$3 -> 50000 | T13: =+VLOOKUP(C13,Indicadores!B:V,21,FALSE) -> 0.9403 | U13: =IF(T13>=100%,"Cumple","No Cumple") -> No Cumple | V13: =IF(T13=100%,S13,0) -> 0 | W13: =IF(AND(G13>=95%,I13>=95%),"SI","NO") -> NO | X13: =+IF(W13="SI",N13+R13+V13,0) -> 0
B14: REGIONAL BOGOTA | C14: CTR_2 | D14: HECTOR MEDINA ROZO | E14: GIL MARTINEZ JENNIFER STEFANNIE | F14: =+$F$4 -> 250000 | G14: =+VLOOKUP(C14,Indicadores!B:C,2,FALSE) -> 0.73967273 | H14: =IF(G14>=95%,"Cumple","No Cumple") -> No Cumple | I14: =+VLOOKUP(C14,Indicadores!B:F,5,FALSE) -> 0.5 | J14: =IF(I14>=95%,"Cumple","No Cumple") -> No Cumple | K14: =+$F$4*$K$3 -> 150000 | L14: =+VLOOKUP(C14,Indicadores!B:P,15,FALSE) -> 0.66163333 | M14: =IF(L14>=80%,"Cumple","No Cumple") -> No Cumple | N14: =IF(L14=80%,K14*70%,IF(AND(L14>=81%,L14<=90%),K14*80%,IF(AND(L14>=91%,L14<=95%),K14*90%,IF(L14=96%,K14*96%,IF(L14=97%,K14*97%,IF(L14=98%,K14*98%,IF(L14=99%,K14*99%,IF(L14=100%,K14,0)))))))) -> 0 | O14: =+$F$4*$O$3 -> 50000 | P14: 0.95 | Q14: =IF(P14>=80%,"Cumple","No Cumple") -> Cumple | R14: =+O14*95% -> 47500 | S14: =+$F$4*$S$3 -> 50000 | T14: =+VLOOKUP(C14,Indicadores!B:V,21,FALSE) -> 0.4091 | U14: =IF(T14>=100%,"Cumple","No Cumple") -> No Cumple | V14: =IF(T14=100%,S14,0) -> 0 | W14: =IF(AND(G14>=95%,I14>=95%),"SI","NO") -> NO | X14: =+IF(W14="SI",N14+R14+V14,0) -> 0
B15: REGIONAL BOGOTA | C15: CTR_3 | D15: HECTOR MEDINA ROZO | E15: GIL MARTINEZ JENNIFER STEFANNIE | F15: =+$F$4 -> 250000 | G15: =+VLOOKUP(C15,Indicadores!B:C,2,FALSE) -> 0.27650909 | H15: =IF(G15>=95%,"Cumple","No Cumple") -> No Cumple | I15: =+VLOOKUP(C15,Indicadores!B:F,5,FALSE) -> 1 | J15: =IF(I15>=95%,"Cumple","No Cumple") -> Cumple | K15: =+$F$4*$K$3 -> 150000 | L15: =+VLOOKUP(C15,Indicadores!B:P,15,FALSE) -> 0.1111 | M15: =IF(L15>=80%,"Cumple","No Cumple") -> No Cumple | N15: =IF(L15=80%,K15*70%,IF(AND(L15>=81%,L15<=90%),K15*80%,IF(AND(L15>=91%,L15<=95%),K15*90%,IF(L15=96%,K15*96%,IF(L15=97%,K15*97%,IF(L15=98%,K15*98%,IF(L15=99%,K15*99%,IF(L15=100%,K15,0)))))))) -> 0 | O15: =+$F$4*$O$3 -> 50000 | P15: 0.95 | Q15: =IF(P15>=80%,"Cumple","No Cumple") -> Cumple | R15: =+O15*95% -> 47500 | S15: =+$F$4*$S$3 -> 50000 | T15: =+VLOOKUP(C15,Indicadores!B:V,21,FALSE) -> 0.375 | U15: =IF(T15>=100%,"Cumple","No Cumple") -> No Cumple | V15: =IF(T15=100%,S15,0) -> 0 | W15: =IF(AND(G15>=95%,I15>=95%),"SI","NO") -> NO | X15: =+IF(W15="SI",N15+R15+V15,0) -> 0
B16: REGIONAL BOGOTA | C16: CTR_4 | D16: ANYI MAYERLIE ORJUELA | E16: SUSANA SILVA MENDOZA | F16: =+$F$4 -> 250000 | G16: =+VLOOKUP(C16,Indicadores!B:C,2,FALSE) -> 0.76430909 | H16: =IF(G16>=95%,"Cumple","No Cumple") -> No Cumple | I16: =+VLOOKUP(C16,Indicadores!B:F,5,FALSE) -> 1 | J16: =IF(I16>=95%,"Cumple","No Cumple") -> Cumple | K16: =+$F$4*$K$3 -> 150000 | L16: =+VLOOKUP(C16,Indicadores!B:P,15,FALSE) -> 0.66666667 | M16: =IF(L16>=80%,"Cumple","No Cumple") -> No Cumple | N16: =IF(L16=80%,K16*70%,IF(AND(L16>=81%,L16<=90%),K16*80%,IF(AND(L16>=91%,L16<=95%),K16*90%,IF(L16=96%,K16*96%,IF(L16=97%,K16*97%,IF(L16=98%,K16*98%,IF(L16=99%,K16*99%,IF(L16=100%,K16,0)))))))) -> 0 | O16: =+$F$4*$O$3 -> 50000 | P16: 0.95 | Q16: =IF(P16>=80%,"Cumple","No Cumple") -> Cumple | R16: =+O16*95% -> 47500 | S16: =+$F$4*$S$3 -> 50000 | T16: =+VLOOKUP(C16,Indicadores!B:V,21,FALSE) -> 1 | U16: =IF(T16>=100%,"Cumple","No Cumple") -> Cumple | V16: =IF(T16=100%,S16,0) -> 50000 | W16: =IF(AND(G16>=95%,I16>=95%),"SI","NO") -> NO | X16: =+IF(W16="SI",N16+R16+V16,0) -> 0
B17: REGIONAL BOGOTA | C17: CTR_5 | D17: ANYI MAYERLIE ORJUELA | E17: SUSANA SILVA MENDOZA | F17: =+$F$4 -> 250000 | G17: =+VLOOKUP(C17,Indicadores!B:C,2,FALSE) -> 0.73865455 | H17: =IF(G17>=95%,"Cumple","No Cumple") -> No Cumple | I17: =+VLOOKUP(C17,Indicadores!B:F,5,FALSE) -> 1 | J17: =IF(I17>=95%,"Cumple","No Cumple") -> Cumple | K17: =+$F$4*$K$3 -> 150000 | L17: =+VLOOKUP(C17,Indicadores!B:P,15,FALSE) -> 0.30556667 | M17: =IF(L17>=80%,"Cumple","No Cumple") -> No Cumple | N17: =IF(L17=80%,K17*70%,IF(AND(L17>=81%,L17<=90%),K17*80%,IF(AND(L17>=91%,L17<=95%),K17*90%,IF(L17=96%,K17*96%,IF(L17=97%,K17*97%,IF(L17=98%,K17*98%,IF(L17=99%,K17*99%,IF(L17=100%,K17,0)))))))) -> 0 | O17: =+$F$4*$O$3 -> 50000 | P17: 0.95 | Q17: =IF(P17>=80%,"Cumple","No Cumple") -> Cumple | R17: =+O17*95% -> 47500 | S17: =+$F$4*$S$3 -> 50000 | T17: =+VLOOKUP(C17,Indicadores!B:V,21,FALSE) -> 0.9167 | U17: =IF(T17>=100%,"Cumple","No Cumple") -> No Cumple | V17: =IF(T17=100%,S17,0) -> 0 | W17: =IF(AND(G17>=95%,I17>=95%),"SI","NO") -> NO | X17: =+IF(W17="SI",N17+R17+V17,0) -> 0
... B95: REGIONAL PERIFERIA | C95: VIJ_9 | D95: HECTOR MEDINA ROZO | E95: GONZALEZ BARRANTES EDWIN JESSID | F95: =+$F$4 -> 250000 | G95: =+VLOOKUP(C95,Indicadores!B:C,2,FALSE) -> 0.54912727 | H95: =IF(G95>=95%,"Cumple","No Cumple") -> No Cumple | I95: =+VLOOKUP(C95,Indicadores!B:F,5,FALSE) -> 1 | J95: =IF(I95>=95%,"Cumple","No Cumple") -> Cumple | K95: =+$F$4*$K$3 -> 150000 | L95: =+VLOOKUP(C95,Indicadores!B:P,15,FALSE) -> 0.32163333 | M95: =IF(L95>=80%,"Cumple","No Cumple") -> No Cumple | N95: =IF(L95=80%,K95*70%,IF(AND(L95>=81%,L95<=90%),K95*80%,IF(AND(L95>=91%,L95<=95%),K95*90%,IF(L95=96%,K95*96%,IF(L95=97%,K95*97%,IF(L95=98%,K95*98%,IF(L95=99%,K95*99%,IF(L95=100%,K95,0)))))))) -> 0 | O95: =+$F$4*$O$3 -> 50000 | P95: 0.95 | Q95: =IF(P95>=80%,"Cumple","No Cumple") -> Cumple | R95: =+O95*95% -> 47500 | S95: =+$F$4*$S$3 -> 50000 | T95: =+VLOOKUP(C95,Indicadores!B:V,21,FALSE) -> 0.802 | U95: =IF(T95>=100%,"Cumple","No Cumple") -> No Cumple | V95: =IF(T95=100%,S95,0) -> 0 | W95: =IF(AND(G95>=95%,I95>=95%),"SI","NO") -> NO | X95: =+IF(W95="SI",N95+R95+V95,0) -> 0
B96: REGIONAL EJE | C96: ARMENIA_1 | D96: MONICA GIRALDO HERNANDEZ | E96: CAMPUZANO IRLET ANDREA | F96: =+$F$4 -> 250000 | G96: =+VLOOKUP(C96,Indicadores!B:C,2,FALSE) -> 0.79049091 | H96: =IF(G96>=95%,"Cumple","No Cumple") -> No Cumple | I96: 0.9 | J96: =IF(I96>=95%,"Cumple","No Cumple") -> No Cumple | K96: =+$F$4*$K$3 -> 150000 | L96: =+VLOOKUP(C96,Indicadores!B:P,15,FALSE) -> 0.7123 | M96: =IF(L96>=80%,"Cumple","No Cumple") -> No Cumple | N96: =IF(L96=80%,K96*70%,IF(AND(L96>=81%,L96<=90%),K96*80%,IF(AND(L96>=91%,L96<=95%),K96*90%,IF(L96=96%,K96*96%,IF(L96=97%,K96*97%,IF(L96=98%,K96*98%,IF(L96=99%,K96*99%,IF(L96=100%,K96,0)))))))) -> 0 | O96: =+$F$4*$O$3 -> 50000 | P96: 0.95 | Q96: =IF(P96>=80%,"Cumple","No Cumple") -> Cumple | R96: =+O96*95% -> 47500 | S96: =+$F$4*$S$3 -> 50000 | T96: =+VLOOKUP(C96,Indicadores!B:V,21,FALSE) -> 0.5 | U96: =IF(T96>=100%,"Cumple","No Cumple") -> No Cumple | V96: =IF(T96=100%,S96,0) -> 0 | W96: =IF(AND(G96>=95%,I96>=95%),"SI","NO") -> NO | X96: =+IF(W96="SI",N96+R96+V96,0) -> 0
B97: REGIONAL EJE | C97: ARMENIA_2 | D97: MONICA GIRALDO HERNANDEZ | E97: CAMPUZANO IRLET ANDREA | F97: =+$F$4 -> 250000 | G97: =+VLOOKUP(C97,Indicadores!B:C,2,FALSE) -> 0.80227273 | H97: =IF(G97>=95%,"Cumple","No Cumple") -> No Cumple | I97: 0.9 | J97: =IF(I97>=95%,"Cumple","No Cumple") -> No Cumple | K97: =+$F$4*$K$3 -> 150000 | L97: =+VLOOKUP(C97,Indicadores!B:P,15,FALSE) -> 0.71583333 | M97: =IF(L97>=80%,"Cumple","No Cumple") -> No Cumple | N97: =IF(L97=80%,K97*70%,IF(AND(L97>=81%,L97<=90%),K97*80%,IF(AND(L97>=91%,L97<=95%),K97*90%,IF(L97=96%,K97*96%,IF(L97=97%,K97*97%,IF(L97=98%,K97*98%,IF(L97=99%,K97*99%,IF(L97=100%,K97,0)))))))) -> 0 | O97: =+$F$4*$O$3 -> 50000 | P97: 0.95 | Q97: =IF(P97>=80%,"Cumple","No Cumple") -> Cumple | R97: =+O97*95% -> 47500 | S97: =+$F$4*$S$3 -> 50000 | T97: =+VLOOKUP(C97,Indicadores!B:V,21,FALSE) -> 0.5 | U97: =IF(T97>=100%,"Cumple","No Cumple") -> No Cumple | V97: =IF(T97=100%,S97,0) -> 0 | W97: =IF(AND(G97>=95%,I97>=95%),"SI","NO") -> NO | X97: =+IF(W97="SI",N97+R97+V97,0) -> 0
B98: REGIONAL EJE | C98: CARTAGO_1 | D98: MONICA GIRALDO HERNANDEZ | E98: CAMPUZANO IRLET ANDREA | F98: =+$F$4 -> 250000 | G98: =+VLOOKUP(C98,Indicadores!B:C,2,FALSE) -> 0.77805455 | H98: =IF(G98>=95%,"Cumple","No Cumple") -> No Cumple | I98: =+VLOOKUP(C98,Indicadores!B:F,5,FALSE) -> 0.94736842 | J98: =IF(I98>=95%,"Cumple","No Cumple") -> No Cumple | K98: =+$F$4*$K$3 -> 150000 | L98: =+VLOOKUP(C98,Indicadores!B:P,15,FALSE) -> 0.7029 | M98: =IF(L98>=80%,"Cumple","No Cumple") -> No Cumple | N98: =IF(L98=80%,K98*70%,IF(AND(L98>=81%,L98<=90%),K98*80%,IF(AND(L98>=91%,L98<=95%),K98*90%,IF(L98=96%,K98*96%,IF(L98=97%,K98*97%,IF(L98=98%,K98*98%,IF(L98=99%,K98*99%,IF(L98=100%,K98,0)))))))) -> 0 | O98: =+$F$4*$O$3 -> 50000 | P98: 0.95 | Q98: =IF(P98>=80%,"Cumple","No Cumple") -> Cumple | R98: =+O98*95% -> 47500 | S98: =+$F$4*$S$3 -> 50000 | T98: =+VLOOKUP(C98,Indicadores!B:V,21,FALSE) -> 0.5 | U98: =IF(T98>=100%,"Cumple","No Cumple") -> No Cumple | V98: =IF(T98=100%,S98,0) -> 0 | W98: =IF(AND(G98>=95%,I98>=95%),"SI","NO") -> NO | X98: =+IF(W98="SI",N98+R98+V98,0) -> 0
B99: REGIONAL EJE | C99: DOSQUEBRADAS_1 | D99: MONICA GIRALDO HERNANDEZ | E99: CAMPUZANO IRLET ANDREA | F99: =+$F$4 -> 250000 | G99: =+VLOOKUP(C99,Indicadores!B:C,2,FALSE) -> 0.53720909 | H99: =IF(G99>=95%,"Cumple","No Cumple") -> No Cumple | I99: =+VLOOKUP(C99,Indicadores!B:F,5,FALSE) -> 1 | J99: =IF(I99>=95%,"Cumple","No Cumple") -> Cumple | K99: =+$F$4*$K$3 -> 150000 | L99: =+VLOOKUP(C99,Indicadores!B:P,15,FALSE) -> 0.57576667 | M99: =IF(L99>=80%,"Cumple","No Cumple") -> No Cumple | N99: =IF(L99=80%,K99*70%,IF(AND(L99>=81%,L99<=90%),K99*80%,IF(AND(L99>=91%,L99<=95%),K99*90%,IF(L99=96%,K99*96%,IF(L99=97%,K99*97%,IF(L99=98%,K99*98%,IF(L99=99%,K99*99%,IF(L99=100%,K99,0)))))))) -> 0 | O99: =+$F$4*$O$3 -> 50000 | P99: 0.95 | Q99: =IF(P99>=80%,"Cumple","No Cumple") -> Cumple | R99: =+O99*95% -> 47500 | S99: =+$F$4*$S$3 -> 50000 | T99: =+VLOOKUP(C99,Indicadores!B:V,21,FALSE) -> 0.7273 | U99: =IF(T99>=100%,"Cumple","No Cumple") -> No Cumple | V99: =IF(T99=100%,S99,0) -> 0 | W99: =IF(AND(G99>=95%,I99>=95%),"SI","NO") -> NO | X99: =+IF(W99="SI",N99+R99+V99,0) -> 0
B100: REGIONAL EJE | C100: DOSQUEBRADAS_2 | D100: MONICA GIRALDO HERNANDEZ | E100: CAMPUZANO IRLET ANDREA | F100: =+$F$4 -> 250000 | G100: =+VLOOKUP(C100,Indicadores!B:C,2,FALSE) -> 0.78260909 | H100: =IF(G100>=95%,"Cumple","No Cumple") -> No Cumple | I100: =+VLOOKUP(C100,Indicadores!B:F,5,FALSE) -> 0.88235294 | J100: =IF(I100>=95%,"Cumple","No Cumple") -> No Cumple | K100: =+$F$4*$K$3 -> 150000 | L100: =+VLOOKUP(C100,Indicadores!B:P,15,FALSE) -> 0.51633333 | M100: =IF(L100>=80%,"Cumple","No Cumple") -> No Cumple | N100: =IF(L100=80%,K100*70%,IF(AND(L100>=81%,L100<=90%),K100*80%,IF(AND(L100>=91%,L100<=95%),K100*90%,IF(L100=96%,K100*96%,IF(L100=97%,K100*97%,IF(L100=98%,K100*98%,IF(L100=99%,K100*99%,IF(L100=100%,K100,0)))))))) -> 0 | O100: =+$F$4*$O$3 -> 50000 | P100: 0.95 | Q100: =IF(P100>=80%,"Cumple","No Cumple") -> Cumple | R100: =+O100*95% -> 47500 | S100: =+$F$4*$S$3 -> 50000 | T100: =+VLOOKUP(C100,Indicadores!B:V,21,FALSE) -> 0.5 | U100: =IF(T100>=100%,"Cumple","No Cumple") -> No Cumple | V100: =IF(T100=100%,S100,0) -> 0 | W100: =IF(AND(G100>=95%,I100>=95%),"SI","NO") -> NO | X100: =+IF(W100="SI",N100+R100+V100,0) -> 0
B101: REGIONAL EJE | C101: MANIZALES_1 | D101: MONICA GIRALDO HERNANDEZ | E101: CAMPUZANO IRLET ANDREA | F101: =+$F$4 -> 250000 | G101: =+VLOOKUP(C101,Indicadores!B:C,2,FALSE) -> 0.8538 | H101: =IF(G101>=95%,"Cumple","No Cumple") -> No Cumple | I101: =+VLOOKUP(C101,Indicadores!B:F,5,FALSE) -> 0.94736842 | J101: =IF(I101>=95%,"Cumple","No Cumple") -> No Cumple | K101: =+$F$4*$K$3 -> 150000 | L101: =+VLOOKUP(C101,Indicadores!B:P,15,FALSE) -> 0.84723333 | M101: =IF(L101>=80%,"Cumple","No Cumple") -> Cumple | N101: =IF(L101=80%,K101*70%,IF(AND(L101>=81%,L101<=90%),K101*80%,IF(AND(L101>=91%,L101<=95%),K101*90%,IF(L101=96%,K101*96%,IF(L101=97%,K101*97%,IF(L101=98%,K101*98%,IF(L101=99%,K101*99%,IF(L101=100%,K101,0)))))))) -> 120000 | O101: =+$F$4*$O$3 -> 50000 | P101: 0.95 | Q101: =IF(P101>=80%,"Cumple","No Cumple") -> Cumple | R101: =+O101*95% -> 47500 | S101: =+$F$4*$S$3 -> 50000 | T101: =+VLOOKUP(C101,Indicadores!B:V,21,FALSE) -> 0.5 | U101: =IF(T101>=100%,"Cumple","No Cumple") -> No Cumple | V101: =IF(T101=100%,S101,0) -> 0 | W101: =IF(AND(G101>=95%,I101>=95%),"SI","NO") -> NO | X101: =+IF(W101="SI",N101+R101+V101,0) -> 0
B102: REGIONAL EJE | C102: MANIZALES_2 | D102: MONICA GIRALDO HERNANDEZ | E102: CAMPUZANO IRLET ANDREA | F102: =+$F$4 -> 250000 | G102: =+VLOOKUP(C102,Indicadores!B:C,2,FALSE) -> 0.76623636 | H102: =IF(G102>=95%,"Cumple","No Cumple") -> No Cumple | I102: =+VLOOKUP(C102,Indicadores!B:F,5,FALSE) -> 0.94444444 | J102: =IF(I102>=95%,"Cumple","No Cumple") -> No Cumple | K102: =+$F$4*$K$3 -> 150000 | L102: =+VLOOKUP(C102,Indicadores!B:P,15,FALSE) -> 0.60383333 | M102: =IF(L102>=80%,"Cumple","No Cumple") -> No Cumple | N102: =IF(L102=80%,K102*70%,IF(AND(L102>=81%,L102<=90%),K102*80%,IF(AND(L102>=91%,L102<=95%),K102*90%,IF(L102=96%,K102*96%,IF(L102=97%,K102*97%,IF(L102=98%,K102*98%,IF(L102=99%,K102*99%,IF(L102=100%,K102,0)))))))) -> 0 | O102: =+$F$4*$O$3 -> 50000 | P102: 0.95 | Q102: =IF(P102>=80%,"Cumple","No Cumple") -> Cumple | R102: =+O102*95% -> 47500 | S102: =+$F$4*$S$3 -> 50000 | T102: =+VLOOKUP(C102,Indicadores!B:V,21,FALSE) -> 0.5 | U102: =IF(T102>=100%,"Cumple","No Cumple") -> No Cumple | V102: =IF(T102=100%,S102,0) -> 0 | W102: =IF(AND(G102>=95%,I102>=95%),"SI","NO") -> NO | X102: =+IF(W102="SI",N102+R102+V102,0) -> 0
B103: REGIONAL EJE | C103: MANIZALES_3 | D103: MONICA GIRALDO HERNANDEZ | E103: CAMPUZANO IRLET ANDREA | F103: =+$F$4 -> 250000 | G103: =+VLOOKUP(C103,Indicadores!B:C,2,FALSE) -> 0.79444545 | H103: =IF(G103>=95%,"Cumple","No Cumple") -> No Cumple | I103: =+VLOOKUP(C103,Indicadores!B:F,5,FALSE) -> 0.88235294 | J103: =IF(I103>=95%,"Cumple","No Cumple") -> No Cumple | K103: =+$F$4*$K$3 -> 150000 | L103: =+VLOOKUP(C103,Indicadores!B:P,15,FALSE) -> 0.61863333 | M103: =IF(L103>=80%,"Cumple","No Cumple") -> No Cumple | N103: =IF(L103=80%,K103*70%,IF(AND(L103>=81%,L103<=90%),K103*80%,IF(AND(L103>=91%,L103<=95%),K103*90%,IF(L103=96%,K103*96%,IF(L103=97%,K103*97%,IF(L103=98%,K103*98%,IF(L103=99%,K103*99%,IF(L103=100%,K103,0)))))))) -> 0 | O103: =+$F$4*$O$3 -> 50000 | P103: 0.95 | Q103: =IF(P103>=80%,"Cumple","No Cumple") -> Cumple | R103: =+O103*95% -> 47500 | S103: =+$F$4*$S$3 -> 50000 | T103: =+VLOOKUP(C103,Indicadores!B:V,21,FALSE) -> 0.991 | U103: =IF(T103>=100%,"Cumple","No Cumple") -> No Cumple | V103: =IF(T103=100%,S103,0) -> 0 | W103: =IF(AND(G103>=95%,I103>=95%),"SI","NO") -> NO | X103: =+IF(W103="SI",N103+R103+V103,0) -> 0
B104: REGIONAL EJE | C104: PEREIRA_1 | D104: MONICA GIRALDO HERNANDEZ | E104: CAMPUZANO IRLET ANDREA | F104: =+$F$4 -> 250000 | G104: =+VLOOKUP(C104,Indicadores!B:C,2,FALSE) -> 0.75879091 | H104: =IF(G104>=95%,"Cumple","No Cumple") -> No Cumple | I104: =+VLOOKUP(C104,Indicadores!B:F,5,FALSE) -> 1 | J104: =IF(I104>=95%,"Cumple","No Cumple") -> Cumple | K104: =+$F$4*$K$3 -> 150000 | L104: =+VLOOKUP(C104,Indicadores!B:P,15,FALSE) -> 0.62816667 | M104: =IF(L104>=80%,"Cumple","No Cumple") -> No Cumple | N104: =IF(L104=80%,K104*70%,IF(AND(L104>=81%,L104<=90%),K104*80%,IF(AND(L104>=91%,L104<=95%),K104*90%,IF(L104=96%,K104*96%,IF(L104=97%,K104*97%,IF(L104=98%,K104*98%,IF(L104=99%,K104*99%,IF(L104=100%,K104,0)))))))) -> 0 | O104: =+$F$4*$O$3 -> 50000 | P104: 0.95 | Q104: =IF(P104>=80%,"Cumple","No Cumple") -> Cumple | R104: =+O104*95% -> 47500 | S104: =+$F$4*$S$3 -> 50000 | T104: =+VLOOKUP(C104,Indicadores!B:V,21,FALSE) -> 0.5 | U104: =IF(T104>=100%,"Cumple","No Cumple") -> No Cumple | V104: =IF(T104=100%,S104,0) -> 0 | W104: =IF(AND(G104>=95%,I104>=95%),"SI","NO") -> NO | X104: =+IF(W104="SI",N104+R104+V104,0) -> 0
B105: REGIONAL EJE | C105: PEREIRA_2 | D105: MONICA GIRALDO HERNANDEZ | E105: CAMPUZANO IRLET ANDREA | F105: =+$F$4 -> 250000 | G105: =+VLOOKUP(C105,Indicadores!B:C,2,FALSE) -> 0.76104545 | H105: =IF(G105>=95%,"Cumple","No Cumple") -> No Cumple | I105: =+VLOOKUP(C105,Indicadores!B:F,5,FALSE) -> 1 | J105: =IF(I105>=95%,"Cumple","No Cumple") -> Cumple | K105: =+$F$4*$K$3 -> 150000 | L105: =+VLOOKUP(C105,Indicadores!B:P,15,FALSE) -> 0.59576667 | M105: =IF(L105>=80%,"Cumple","No Cumple") -> No Cumple | N105: =IF(L105=80%,K105*70%,IF(AND(L105>=81%,L105<=90%),K105*80%,IF(AND(L105>=91%,L105<=95%),K105*90%,IF(L105=96%,K105*96%,IF(L105=97%,K105*97%,IF(L105=98%,K105*98%,IF(L105=99%,K105*99%,IF(L105=100%,K105,0)))))))) -> 0 | O105: =+$F$4*$O$3 -> 50000 | P105: 0.95 | Q105: =IF(P105>=80%,"Cumple","No Cumple") -> Cumple | R105: =+O105*95% -> 47500 | S105: =+$F$4*$S$3 -> 50000 | T105: =+VLOOKUP(C105,Indicadores!B:V,21,FALSE) -> 0.5 | U105: =IF(T105>=100%,"Cumple","No Cumple") -> No Cumple | V105: =IF(T105=100%,S105,0) -> 0 | W105: =IF(AND(G105>=95%,I105>=95%),"SI","NO") -> NO | X105: =+IF(W105="SI",N105+R105+V105,0) -> 0
B106: REGIONAL PACIFICO | C106: BUGA_1 | D106: MONICA GIRALDO HERNANDEZ | E106: ROSERO JURADO LAURA CATALINA | F106: =+$F$4 -> 250000 | G106: =+VLOOKUP(C106,Indicadores!B:C,2,FALSE) -> 0.78153636 | H106: =IF(G106>=95%,"Cumple","No Cumple") -> No Cumple | I106: =+VLOOKUP(C106,Indicadores!B:F,5,FALSE) -> 0.92307692 | J106: =IF(I106>=95%,"Cumple","No Cumple") -> No Cumple | K106: =+$F$4*$K$3 -> 150000 | L106: =+VLOOKUP(C106,Indicadores!B:P,15,FALSE) -> 0.38013333 | M106: =IF(L106>=80%,"Cumple","No Cumple") -> No Cumple | N106: =IF(L106=80%,K106*70%,IF(AND(L106>=81%,L106<=90%),K106*80%,IF(AND(L106>=91%,L106<=95%),K106*90%,IF(L106=96%,K106*96%,IF(L106=97%,K106*97%,IF(L106=98%,K106*98%,IF(L106=99%,K106*99%,IF(L106=100%,K106,0)))))))) -> 0 | O106: =+$F$4*$O$3 -> 50000 | P106: 0.95 | Q106: =IF(P106>=80%,"Cumple","No Cumple") -> Cumple | R106: =+O106*95% -> 47500 | S106: =+$F$4*$S$3 -> 50000 | T106: =+VLOOKUP(C106,Indicadores!B:V,21,FALSE) -> 0.9825 | U106: =IF(T106>=100%,"Cumple","No Cumple") -> No Cumple | V106: =IF(T106=100%,S106,0) -> 0 | W106: =IF(AND(G106>=95%,I106>=95%),"SI","NO") -> NO | X106: =+IF(W106="SI",N106+R106+V106,0) -> 0
B107: REGIONAL PACIFICO | C107: CALI_1 | D107: MONICA GIRALDO HERNANDEZ | E107: ROSERO JURADO LAURA CATALINA | F107: =+$F$4 -> 250000 | G107: =+VLOOKUP(C107,Indicadores!B:C,2,FALSE) -> 0.73636364 | H107: =IF(G107>=95%,"Cumple","No Cumple") -> No Cumple | I107: =+VLOOKUP(C107,Indicadores!B:F,5,FALSE) -> 0.66666667 | J107: =IF(I107>=95%,"Cumple","No Cumple") -> No Cumple | K107: =+$F$4*$K$3 -> 150000 | L107: =+VLOOKUP(C107,Indicadores!B:P,15,FALSE) -> 0.3611 | M107: =IF(L107>=80%,"Cumple","No Cumple") -> No Cumple | N107: =IF(L107=80%,K107*70%,IF(AND(L107>=81%,L107<=90%),K107*80%,IF(AND(L107>=91%,L107<=95%),K107*90%,IF(L107=96%,K107*96%,IF(L107=97%,K107*97%,IF(L107=98%,K107*98%,IF(L107=99%,K107*99%,IF(L107=100%,K107,0)))))))) -> 0 | O107: =+$F$4*$O$3 -> 50000 | P107: 0.95 | Q107: =IF(P107>=80%,"Cumple","No Cumple") -> Cumple | R107: =+O107*95% -> 47500 | S107: =+$F$4*$S$3 -> 50000 | T107: =+VLOOKUP(C107,Indicadores!B:V,21,FALSE) -> 1 | U107: =IF(T107>=100%,"Cumple","No Cumple") -> Cumple | V107: =IF(T107=100%,S107,0) -> 50000 | W107: =IF(AND(G107>=95%,I107>=95%),"SI","NO") -> NO | X107: =+IF(W107="SI",N107+R107+V107,0) -> 0
B108: REGIONAL PACIFICO | C108: CALI_14 | D108: MONICA GIRALDO HERNANDEZ | E108: ROSERO JURADO LAURA CATALINA | F108: =+$F$4 -> 250000 | G108: =+VLOOKUP(C108,Indicadores!B:C,2,FALSE) -> 0.80775455 | H108: =IF(G108>=95%,"Cumple","No Cumple") -> No Cumple | I108: =+VLOOKUP(C108,Indicadores!B:F,5,FALSE) -> 1 | J108: =IF(I108>=95%,"Cumple","No Cumple") -> Cumple | K108: =+$F$4*$K$3 -> 150000 | L108: =+VLOOKUP(C108,Indicadores!B:P,15,FALSE) -> 0.3552 | M108: =IF(L108>=80%,"Cumple","No Cumple") -> No Cumple | N108: =IF(L108=80%,K108*70%,IF(AND(L108>=81%,L108<=90%),K108*80%,IF(AND(L108>=91%,L108<=95%),K108*90%,IF(L108=96%,K108*96%,IF(L108=97%,K108*97%,IF(L108=98%,K108*98%,IF(L108=99%,K108*99%,IF(L108=100%,K108,0)))))))) -> 0 | O108: =+$F$4*$O$3 -> 50000 | P108: 0.95 | Q108: =IF(P108>=80%,"Cumple","No Cumple") -> Cumple | R108: =+O108*95% -> 47500 | S108: =+$F$4*$S$3 -> 50000 | T108: =+VLOOKUP(C108,Indicadores!B:V,21,FALSE) -> 0.5 | U108: =IF(T108>=100%,"Cumple","No Cumple") -> No Cumple | V108: =IF(T108=100%,S108,0) -> 0 | W108: =IF(AND(G108>=95%,I108>=95%),"SI","NO") -> NO | X108: =+IF(W108="SI",N108+R108+V108,0) -> 0
B109: REGIONAL PACIFICO | C109: CALI_3 | D109: MONICA GIRALDO HERNANDEZ | E109: ROSERO JURADO LAURA CATALINA | F109: =+$F$4 -> 250000 | G109: =+VLOOKUP(C109,Indicadores!B:C,2,FALSE) -> 0.77181818 | H109: =IF(G109>=95%,"Cumple","No Cumple") -> No Cumple | I109: =+VLOOKUP(C109,Indicadores!B:F,5,FALSE) -> 1 | J109: =IF(I109>=95%,"Cumple","No Cumple") -> Cumple | K109: =+$F$4*$K$3 -> 150000 | L109: =+VLOOKUP(C109,Indicadores!B:P,15,FALSE) -> 0.41296667 | M109: =IF(L109>=80%,"Cumple","No Cumple") -> No Cumple | N109: =IF(L109=80%,K109*70%,IF(AND(L109>=81%,L109<=90%),K109*80%,IF(AND(L109>=91%,L109<=95%),K109*90%,IF(L109=96%,K109*96%,IF(L109=97%,K109*97%,IF(L109=98%,K109*98%,IF(L109=99%,K109*99%,IF(L109=100%,K109,0)))))))) -> 0 | O109: =+$F$4*$O$3 -> 50000 | P109: 0.95 | Q109: =IF(P109>=80%,"Cumple","No Cumple") -> Cumple | R109: =+O109*95% -> 47500 | S109: =+$F$4*$S$3 -> 50000 | T109: =+VLOOKUP(C109,Indicadores!B:V,21,FALSE) -> 1 | U109: =IF(T109>=100%,"Cumple","No Cumple") -> Cumple | V109: =IF(T109=100%,S109,0) -> 50000 | W109: =IF(AND(G109>=95%,I109>=95%),"SI","NO") -> NO | X109: =+IF(W109="SI",N109+R109+V109,0) -> 0
... B132: REGIONAL BOGOTA | C132: SOC_5 | D132: ANYI MAYERLIE ORJUELA | E132: PIÑEROS MONTAÑA LAURA ESTEPHANIA | F132: =+$F$4 -> 250000 | G132: =+VLOOKUP(C132,Indicadores!B:C,2,FALSE) -> 0.80537273 | H132: =IF(G132>=95%,"Cumple","No Cumple") -> No Cumple | I132: =+VLOOKUP(C132,Indicadores!B:F,5,FALSE) -> 1 | J132: =IF(I132>=95%,"Cumple","No Cumple") -> Cumple | K132: =+$F$4*$K$3 -> 150000 | L132: =+VLOOKUP(C132,Indicadores!B:P,15,FALSE) -> 0.5845 | M132: =IF(L132>=80%,"Cumple","No Cumple") -> No Cumple | N132: =IF(L132=80%,K132*70%,IF(AND(L132>=81%,L132<=90%),K132*80%,IF(AND(L132>=91%,L132<=95%),K132*90%,IF(L132=96%,K132*96%,IF(L132=97%,K132*97%,IF(L132=98%,K132*98%,IF(L132=99%,K132*99%,IF(L132=100%,K132,0)))))))) -> 0 | O132: =+$F$4*$O$3 -> 50000 | P132: 0.95 | Q132: =IF(P132>=80%,"Cumple","No Cumple") -> Cumple | R132: =+O132*95% -> 47500 | S132: =+$F$4*$S$3 -> 50000 | T132: =+VLOOKUP(C132,Indicadores!B:V,21,FALSE) -> 1 | U132: =IF(T132>=100%,"Cumple","No Cumple") -> Cumple | V132: =IF(T132=100%,S132,0) -> 50000 | W132: =IF(AND(G132>=95%,I132>=95%),"SI","NO") -> NO | X132: =+IF(W132="SI",N132+R132+V132,0) -> 0
B133: REGIONAL BOGOTA | C133: SOC_6 | D133: ANYI MAYERLIE ORJUELA | E133: PIÑEROS MONTAÑA LAURA ESTEPHANIA | F133: =+$F$4 -> 250000 | G133: =+VLOOKUP(C133,Indicadores!B:C,2,FALSE) -> 0.91861818 | H133: =IF(G133>=95%,"Cumple","No Cumple") -> No Cumple | I133: 0.95 | J133: =IF(I133>=95%,"Cumple","No Cumple") -> Cumple | K133: =+$F$4*$K$3 -> 150000 | L133: =+VLOOKUP(C133,Indicadores!B:P,15,FALSE) -> 0.9345 | M133: =IF(L133>=80%,"Cumple","No Cumple") -> Cumple | N133: =IF(L133=80%,K133*70%,IF(AND(L133>=81%,L133<=90%),K133*80%,IF(AND(L133>=91%,L133<=95%),K133*90%,IF(L133=96%,K133*96%,IF(L133=97%,K133*97%,IF(L133=98%,K133*98%,IF(L133=99%,K133*99%,IF(L133=100%,K133,0)))))))) -> 135000 | O133: =+$F$4*$O$3 -> 50000 | P133: 0.95 | Q133: =IF(P133>=80%,"Cumple","No Cumple") -> Cumple | R133: =+O133*95% -> 47500 | S133: =+$F$4*$S$3 -> 50000 | T133: =+VLOOKUP(C133,Indicadores!B:V,21,FALSE) -> 1 | U133: =IF(T133>=100%,"Cumple","No Cumple") -> Cumple | V133: =IF(T133=100%,S133,0) -> 50000 | W133: =IF(AND(G133>=95%,I133>=95%),"SI","NO") -> NO | X133: =+IF(W133="SI",N133+R133+V133,0) -> 0
B134: REGIONAL BOGOTA | C134: SOC_7 | D134: ANYI MAYERLIE ORJUELA | E134: PIÑEROS MONTAÑA LAURA ESTEPHANIA | F134: =+$F$4 -> 250000 | G134: =+VLOOKUP(C134,Indicadores!B:C,2,FALSE) -> 0.79864545 | H134: =IF(G134>=95%,"Cumple","No Cumple") -> No Cumple | I134: =+VLOOKUP(C134,Indicadores!B:F,5,FALSE) -> 0.95652174 | J134: =IF(I134>=95%,"Cumple","No Cumple") -> Cumple | K134: =+$F$4*$K$3 -> 150000 | L134: =+VLOOKUP(C134,Indicadores!B:P,15,FALSE) -> 0.5323 | M134: =IF(L134>=80%,"Cumple","No Cumple") -> No Cumple | N134: =IF(L134=80%,K134*70%,IF(AND(L134>=81%,L134<=90%),K134*80%,IF(AND(L134>=91%,L134<=95%),K134*90%,IF(L134=96%,K134*96%,IF(L134=97%,K134*97%,IF(L134=98%,K134*98%,IF(L134=99%,K134*99%,IF(L134=100%,K134,0)))))))) -> 0 | O134: =+$F$4*$O$3 -> 50000 | P134: 0.95 | Q134: =IF(P134>=80%,"Cumple","No Cumple") -> Cumple | R134: =+O134*95% -> 47500 | S134: =+$F$4*$S$3 -> 50000 | T134: =+VLOOKUP(C134,Indicadores!B:V,21,FALSE) -> 1 | U134: =IF(T134>=100%,"Cumple","No Cumple") -> Cumple | V134: =IF(T134=100%,S134,0) -> 50000 | W134: =IF(AND(G134>=95%,I134>=95%),"SI","NO") -> NO | X134: =+IF(W134="SI",N134+R134+V134,0) -> 0
B135: REGIONAL BOGOTA | C135: SOC_8 | D135: ANYI MAYERLIE ORJUELA | E135: PIÑEROS MONTAÑA LAURA ESTEPHANIA | F135: =+$F$4 -> 250000 | G135: =+VLOOKUP(C135,Indicadores!B:C,2,FALSE) -> 0.74747273 | H135: =IF(G135>=95%,"Cumple","No Cumple") -> No Cumple | I135: =+VLOOKUP(C135,Indicadores!B:F,5,FALSE) -> 0.9375 | J135: =IF(I135>=95%,"Cumple","No Cumple") -> No Cumple | K135: =+$F$4*$K$3 -> 150000 | L135: =+VLOOKUP(C135,Indicadores!B:P,15,FALSE) -> 0.50306667 | M135: =IF(L135>=80%,"Cumple","No Cumple") -> No Cumple | N135: =IF(L135=80%,K135*70%,IF(AND(L135>=81%,L135<=90%),K135*80%,IF(AND(L135>=91%,L135<=95%),K135*90%,IF(L135=96%,K135*96%,IF(L135=97%,K135*97%,IF(L135=98%,K135*98%,IF(L135=99%,K135*99%,IF(L135=100%,K135,0)))))))) -> 0 | O135: =+$F$4*$O$3 -> 50000 | P135: 0.95 | Q135: =IF(P135>=80%,"Cumple","No Cumple") -> Cumple | R135: =+O135*95% -> 47500 | S135: =+$F$4*$S$3 -> 50000 | T135: =+VLOOKUP(C135,Indicadores!B:V,21,FALSE) -> 0.9899 | U135: =IF(T135>=100%,"Cumple","No Cumple") -> No Cumple | V135: =IF(T135=100%,S135,0) -> 0 | W135: =IF(AND(G135>=95%,I135>=95%),"SI","NO") -> NO | X135: =+IF(W135="SI",N135+R135+V135,0) -> 0
B136: REGIONAL BOGOTA | C136: SOC_9 | D136: ANYI MAYERLIE ORJUELA | E136: PIÑEROS MONTAÑA LAURA ESTEPHANIA | F136: =+$F$4 -> 250000 | G136: =+VLOOKUP(C136,Indicadores!B:C,2,FALSE) -> 0.87151818 | H136: =IF(G136>=95%,"Cumple","No Cumple") -> No Cumple | I136: =+VLOOKUP(C136,Indicadores!B:F,5,FALSE) -> 1 | J136: =IF(I136>=95%,"Cumple","No Cumple") -> Cumple | K136: =+$F$4*$K$3 -> 150000 | L136: =+VLOOKUP(C136,Indicadores!B:P,15,FALSE) -> 0.95853333 | M136: =IF(L136>=80%,"Cumple","No Cumple") -> Cumple | N136: =IF(L136=80%,K136*70%,IF(AND(L136>=81%,L136<=90%),K136*80%,IF(AND(L136>=91%,L136<=95%),K136*90%,IF(L136=96%,K136*96%,IF(L136=97%,K136*97%,IF(L136=98%,K136*98%,IF(L136=99%,K136*99%,IF(L136=100%,K136,0)))))))) -> 0 | O136: =+$F$4*$O$3 -> 50000 | P136: 0.95 | Q136: =IF(P136>=80%,"Cumple","No Cumple") -> Cumple | R136: =+O136*95% -> 47500 | S136: =+$F$4*$S$3 -> 50000 | T136: =+VLOOKUP(C136,Indicadores!B:V,21,FALSE) -> 1 | U136: =IF(T136>=100%,"Cumple","No Cumple") -> Cumple | V136: =IF(T136=100%,S136,0) -> 50000 | W136: =IF(AND(G136>=95%,I136>=95%),"SI","NO") -> NO | X136: =+IF(W136="SI",N136+R136+V136,0) -> 0
B137: REGIONAL ESTE | C137: BARRANCABERMEJA_1 | D137: MONICA GIRALDO HERNANDEZ | E137: SÁNCHEZ ZAMBRANO LEIDY NICOLE VANESSA | F137: =+$F$4 -> 250000 | G137: =+VLOOKUP(C137,Indicadores!B:C,2,FALSE) -> 0.81480909 | H137: =IF(G137>=95%,"Cumple","No Cumple") -> No Cumple | I137: =+VLOOKUP(C137,Indicadores!B:F,5,FALSE) -> 1 | J137: =IF(I137>=95%,"Cumple","No Cumple") -> Cumple | K137: =+$F$4*$K$3 -> 150000 | L137: =+VLOOKUP(C137,Indicadores!B:P,15,FALSE) -> 0.53613333 | M137: =IF(L137>=80%,"Cumple","No Cumple") -> No Cumple | N137: =IF(L137=80%,K137*70%,IF(AND(L137>=81%,L137<=90%),K137*80%,IF(AND(L137>=91%,L137<=95%),K137*90%,IF(L137=96%,K137*96%,IF(L137=97%,K137*97%,IF(L137=98%,K137*98%,IF(L137=99%,K137*99%,IF(L137=100%,K137,0)))))))) -> 0 | O137: =+$F$4*$O$3 -> 50000 | P137: 0.95 | Q137: =IF(P137>=80%,"Cumple","No Cumple") -> Cumple | R137: =+O137*95% -> 47500 | S137: =+$F$4*$S$3 -> 50000 | T137: =+VLOOKUP(C137,Indicadores!B:V,21,FALSE) -> 0.5 | U137: =IF(T137>=100%,"Cumple","No Cumple") -> No Cumple | V137: =IF(T137=100%,S137,0) -> 0 | W137: =IF(AND(G137>=95%,I137>=95%),"SI","NO") -> NO | X137: =+IF(W137="SI",N137+R137+V137,0) -> 0
B138: REGIONAL ESTE | C138: BARRANCABERMEJA_2 | D138: MONICA GIRALDO HERNANDEZ | E138: SÁNCHEZ ZAMBRANO LEIDY NICOLE VANESSA | F138: =+$F$4 -> 250000 | G138: =+VLOOKUP(C138,Indicadores!B:C,2,FALSE) -> 0.75973636 | H138: =IF(G138>=95%,"Cumple","No Cumple") -> No Cumple | I138: =+VLOOKUP(C138,Indicadores!B:F,5,FALSE) -> 1 | J138: =IF(I138>=95%,"Cumple","No Cumple") -> Cumple | K138: =+$F$4*$K$3 -> 150000 | L138: =+VLOOKUP(C138,Indicadores!B:P,15,FALSE) -> 0.70236667 | M138: =IF(L138>=80%,"Cumple","No Cumple") -> No Cumple | N138: =IF(L138=80%,K138*70%,IF(AND(L138>=81%,L138<=90%),K138*80%,IF(AND(L138>=91%,L138<=95%),K138*90%,IF(L138=96%,K138*96%,IF(L138=97%,K138*97%,IF(L138=98%,K138*98%,IF(L138=99%,K138*99%,IF(L138=100%,K138,0)))))))) -> 0 | O138: =+$F$4*$O$3 -> 50000 | P138: 0.95 | Q138: =IF(P138>=80%,"Cumple","No Cumple") -> Cumple | R138: =+O138*95% -> 47500 | S138: =+$F$4*$S$3 -> 50000 | T138: =+VLOOKUP(C138,Indicadores!B:V,21,FALSE) -> 1 | U138: =IF(T138>=100%,"Cumple","No Cumple") -> Cumple | V138: =IF(T138=100%,S138,0) -> 50000 | W138: =IF(AND(G138>=95%,I138>=95%),"SI","NO") -> NO | X138: =+IF(W138="SI",N138+R138+V138,0) -> 0
B139: REGIONAL ESTE | C139: BUCARAMANGA_1 | D139: MONICA GIRALDO HERNANDEZ | E139: SÁNCHEZ ZAMBRANO LEIDY NICOLE VANESSA | F139: =+$F$4 -> 250000 | G139: =+VLOOKUP(C139,Indicadores!B:C,2,FALSE) -> 0.76018182 | H139: =IF(G139>=95%,"Cumple","No Cumple") -> No Cumple | I139: 1 | J139: =IF(I139>=95%,"Cumple","No Cumple") -> Cumple | K139: =+$F$4*$K$3 -> 150000 | L139: =+VLOOKUP(C139,Indicadores!B:P,15,FALSE) -> 0.58906667 | M139: =IF(L139>=80%,"Cumple","No Cumple") -> No Cumple | N139: =IF(L139=80%,K139*70%,IF(AND(L139>=81%,L139<=90%),K139*80%,IF(AND(L139>=91%,L139<=95%),K139*90%,IF(L139=96%,K139*96%,IF(L139=97%,K139*97%,IF(L139=98%,K139*98%,IF(L139=99%,K139*99%,IF(L139=100%,K139,0)))))))) -> 0 | O139: =+$F$4*$O$3 -> 50000 | P139: 0.95 | Q139: =IF(P139>=80%,"Cumple","No Cumple") -> Cumple | R139: =+O139*95% -> 47500 | S139: =+$F$4*$S$3 -> 50000 | T139: =+VLOOKUP(C139,Indicadores!B:V,21,FALSE) -> 1 | U139: =IF(T139>=100%,"Cumple","No Cumple") -> Cumple | V139: =IF(T139=100%,S139,0) -> 50000 | W139: =IF(AND(G139>=95%,I139>=95%),"SI","NO") -> NO | X139: =+IF(W139="SI",N139+R139+V139,0) -> 0
...

Sheet Liq. Mercaderista 3ra Llave 70%
Z1: SI | AA1: =+COUNTIF(Z6:Z193,Z1) -> 169
B2: LLAVE DEL 70%
H3: LLAVE | L3: LLAVE | N3: 0.6 | R3: 0.2 | V3: 0.2
F4: 250000 | G4: CAPTURA DE INFORMACION | J4: COBERTURA | N4: TIENDA PERFECTA | R4: VENTAS | V4: DEVOLUCIONES & FECHAS CORTAS | AA4: =+SUBTOTAL(9,AA6:AA193) -> 23781000
B5: Regional | C5: RUTA | D5: Lider | E5: Supervisor | F5: Valor Comision Efectividad | G5: % Cumpl. Captura | H5: Categoria Efec 70% | I5: $ Liquidar | J5: Valor Comision Cobertura | K5: % Cumplimiento Cobertura | L5: Categoria Efec 70% | M5: $ Liquidar | N5: Valor Comision TP | O5: % Cumplimiento TP | P5: Categoria Efec >80% | Q5: $ Liquidar | R5: Valor Comision Ventas | S5: % Cumplimiento Ventas | T5: Categoria Efec | U5: $ Liquidar | V5: Valor Comision FC y Dev | W5: % Cumplimiento FC & DV | X5: Categoria Efec | Y5: $ Liquidar | Z5: Corresponde Comision | AA5: Valor total A Pagar Real | AB5: Observaciones
B6: REGIONAL BOGOTA | C6: CTR_1 | D6: ANYI MAYERLIE ORJUELA | E6: ADRIANA MARCELA DIAZ RICO | F6: =+$F$4*$G$3 -> 0 | G6: =+VLOOKUP(C6,Indicadores!B:C,2,FALSE) -> 0.8841 | H6: =IF(G6>=70%,"Cumple","No Cumple") -> Cumple | I6: =+IF(G6>=95%,F6*G6,0) -> 0 | J6: =+$F$4*$J$3 -> 0 | K6: =+VLOOKUP(C6,Indicadores!B:F,5,FALSE) -> 1 | L6: =IF(K6>=70%,"Cumple","No Cumple") -> Cumple | M6: =+IF(K6>=95%,J6*K6,0) -> 0 | N6: =+$F$4*$N$3 -> 150000 | O6: 0.98 | P6: =IF(O6>=80%,"Cumple","No Cumple") -> Cumple | Q6: =IF(O6=80%,N6*70%,IF(AND(O6>=81%,O6<=90%),N6*80%,IF(AND(O6>=91%,O6<=95%),N6*90%,IF(O6=96%,N6*96%,IF(O6=97%,N6*97%,IF(O6=98%,N6*98%,IF(O6=99%,N6*99%,IF(O6=100%,N6,0)))))))) -> 147000 | R6: =+$F$4*$R$3 -> 50000 | S6: =+VLOOKUP(C6,Indicadores!B:Q,15,FALSE) -> 0.86933333 | T6: =IF(S6>=80%,"Cumple","No Cumple") -> Cumple | U6: =IF(S6=80%,R6*70%,IF(AND(S6>=81%,S6<=90%),R6*80%,IF(AND(S6>=91%,S6<=95%),R6*90%,IF(S6=96%,R6*96%,IF(S6=97%,R6*97%,IF(S6=98%,R6*98%,IF(S6=99%,R6*99%,IF(S6=100%,R6,0)))))))) -> 40000 | V6: =+$F$4*$V$3 -> 50000 | W6: =+VLOOKUP(C6,Indicadores!B:V,21,FALSE) -> 0.489 | X6: =IF(W6>=100%,"Cumple","No Cumple") -> No Cumple | Y6: =IF(W6=100%,V6,0) -> 0 | Z6: =IF(AND(G6>=70%,K6>=70%),"SI","NO") -> SI | AA6: =+IF(Z6="SI",Q6+U6+Y6,0) -> 187000
B7: REGIONAL BOGOTA | C7: CTR_10 | D7: ANYI MAYERLIE ORJUELA | E7: ADRIANA MARCELA DIAZ RICO | F7: =+$F$4*$G$3 -> 0 | G7: =+VLOOKUP(C7,Indicadores!B:C,2,FALSE) -> 0.7519 | H7: =IF(G7>=70%,"Cumple","No Cumple") -> Cumple | I7: =+IF(G7>=95%,F7*G7,0) -> 0 | J7: =+$F$4*$J$3 -> 0 | K7: =+VLOOKUP(C7,Indicadores!B:F,5,FALSE) -> 1 | L7: =IF(K7>=70%,"Cumple","No Cumple") -> Cumple | M7: =+IF(K7>=95%,J7*K7,0) -> 0 | N7: =+$F$4*$N$3 -> 150000 | O7: =+VLOOKUP(C7,Indicadores!B:P,14,FALSE) -> 1 | P7: =IF(O7>=80%,"Cumple","No Cumple") -> Cumple | Q7: =IF(O7=80%,N7*70%,IF(AND(O7>=81%,O7<=90%),N7*80%,IF(AND(O7>=91%,O7<=95%),N7*90%,IF(O7=96%,N7*96%,IF(O7=97%,N7*97%,IF(O7=98%,N7*98%,IF(O7=99%,N7*99%,IF(O7=100%,N7,0)))))))) -> 150000 | R7: =+$F$4*$R$3 -> 50000 | S7: =+VLOOKUP(C7,Indicadores!B:Q,15,FALSE) -> 0.40476667 | T7: =IF(S7>=80%,"Cumple","No Cumple") -> No Cumple | U7: =IF(S7=80%,R7*70%,IF(AND(S7>=81%,S7<=90%),R7*80%,IF(AND(S7>=91%,S7<=95%),R7*90%,IF(S7=96%,R7*96%,IF(S7=97%,R7*97%,IF(S7=98%,R7*98%,IF(S7=99%,R7*99%,IF(S7=100%,R7,0)))))))) -> 0 | V7: =+$F$4*$V$3 -> 50000 | W7: =+VLOOKUP(C7,Indicadores!B:V,21,FALSE) -> 1 | X7: =IF(W7>=100%,"Cumple","No Cumple") -> Cumple | Y7: =IF(W7=100%,V7,0) -> 50000 | Z7: =IF(AND(G7>=70%,K7>=70%),"SI","NO") -> SI | AA7: =+IF(Z7="SI",Q7+U7+Y7,0) -> 200000
B8: REGIONAL BOGOTA | C8: CTR_11 | D8: ANYI MAYERLIE ORJUELA | E8: ADRIANA MARCELA DIAZ RICO | F8: =+$F$4*$G$3 -> 0 | G8: =+VLOOKUP(C8,Indicadores!B:C,2,FALSE) -> 0.75821818 | H8: =IF(G8>=70%,"Cumple","No Cumple") -> Cumple | I8: =+IF(G8>=95%,F8*G8,0) -> 0 | J8: =+$F$4*$J$3 -> 0 | K8: =+VLOOKUP(C8,Indicadores!B:F,5,FALSE) -> 0.44444444 | L8: =IF(K8>=70%,"Cumple","No Cumple") -> No Cumple | M8: =+IF(K8>=95%,J8*K8,0) -> 0 | N8: =+$F$4*$N$3 -> 150000 | O8: 0.99 | P8: =IF(O8>=80%,"Cumple","No Cumple") -> Cumple | Q8: =IF(O8=80%,N8*70%,IF(AND(O8>=81%,O8<=90%),N8*80%,IF(AND(O8>=91%,O8<=95%),N8*90%,IF(O8=96%,N8*96%,IF(O8=97%,N8*97%,IF(O8=98%,N8*98%,IF(O8=99%,N8*99%,IF(O8=100%,N8,0)))))))) -> 148500 | R8: =+$F$4*$R$3 -> 50000 | S8: =+VLOOKUP(C8,Indicadores!B:Q,15,FALSE) -> 0.39656667 | T8: =IF(S8>=80%,"Cumple","No Cumple") -> No Cumple | U8: =IF(S8=80%,R8*70%,IF(AND(S8>=81%,S8<=90%),R8*80%,IF(AND(S8>=91%,S8<=95%),R8*90%,IF(S8=96%,R8*96%,IF(S8=97%,R8*97%,IF(S8=98%,R8*98%,IF(S8=99%,R8*99%,IF(S8=100%,R8,0)))))))) -> 0 | V8: =+$F$4*$V$3 -> 50000 | W8: =+VLOOKUP(C8,Indicadores!B:V,21,FALSE) -> 0.48935 | X8: =IF(W8>=100%,"Cumple","No Cumple") -> No Cumple | Y8: =IF(W8=100%,V8,0) -> 0 | Z8: =IF(AND(G8>=70%,K8>=70%),"SI","NO") -> NO | AA8: =+IF(Z8="SI",Q8+U8+Y8,0) -> 0
B9: REGIONAL BOGOTA | C9: CTR_12 | D9: ANYI MAYERLIE ORJUELA | E9: ADRIANA MARCELA DIAZ RICO | F9: =+$F$4*$G$3 -> 0 | G9: =+VLOOKUP(C9,Indicadores!B:C,2,FALSE) -> 0.70937273 | H9: =IF(G9>=70%,"Cumple","No Cumple") -> Cumple | I9: =+IF(G9>=95%,F9*G9,0) -> 0 | J9: =+$F$4*$J$3 -> 0 | K9: =+VLOOKUP(C9,Indicadores!B:F,5,FALSE) -> 0.82608696 | L9: =IF(K9>=70%,"Cumple","No Cumple") -> Cumple | M9: =+IF(K9>=95%,J9*K9,0) -> 0 | N9: =+$F$4*$N$3 -> 150000 | O9: =+VLOOKUP(C9,Indicadores!B:P,14,FALSE) -> 0.9394 | P9: =IF(O9>=80%,"Cumple","No Cumple") -> Cumple | Q9: =IF(O9=80%,N9*70%,IF(AND(O9>=81%,O9<=90%),N9*80%,IF(AND(O9>=91%,O9<=95%),N9*90%,IF(O9=96%,N9*96%,IF(O9=97%,N9*97%,IF(O9=98%,N9*98%,IF(O9=99%,N9*99%,IF(O9=100%,N9,0)))))))) -> 135000 | R9: =+$F$4*$R$3 -> 50000 | S9: =+VLOOKUP(C9,Indicadores!B:Q,15,FALSE) -> 0.35353333 | T9: =IF(S9>=80%,"Cumple","No Cumple") -> No Cumple | U9: =IF(S9=80%,R9*70%,IF(AND(S9>=81%,S9<=90%),R9*80%,IF(AND(S9>=91%,S9<=95%),R9*90%,IF(S9=96%,R9*96%,IF(S9=97%,R9*97%,IF(S9=98%,R9*98%,IF(S9=99%,R9*99%,IF(S9=100%,R9,0)))))))) -> 0 | V9: =+$F$4*$V$3 -> 50000 | W9: =+VLOOKUP(C9,Indicadores!B:V,21,FALSE) -> 0.4697 | X9: =IF(W9>=100%,"Cumple","No Cumple") -> No Cumple | Y9: =IF(W9=100%,V9,0) -> 0 | Z9: =IF(AND(G9>=70%,K9>=70%),"SI","NO") -> SI | AA9: =+IF(Z9="SI",Q9+U9+Y9,0) -> 135000
B10: REGIONAL BOGOTA | C10: CTR_13 | D10: ANYI MAYERLIE ORJUELA | E10: ADRIANA MARCELA DIAZ RICO | F10: =+$F$4*$G$3 -> 0 | G10: 0.7 | H10: =IF(G10>=70%,"Cumple","No Cumple") -> Cumple | I10: =+IF(G10>=95%,F10*G10,0) -> 0 | J10: =+$F$4*$J$3 -> 0 | K10: =+VLOOKUP(C10,Indicadores!B:F,5,FALSE) -> 1 | L10: =IF(K10>=70%,"Cumple","No Cumple") -> Cumple | M10: =+IF(K10>=95%,J10*K10,0) -> 0 | N10: =+$F$4*$N$3 -> 150000 | O10: =+VLOOKUP(C10,Indicadores!B:P,14,FALSE) -> 1 | P10: =IF(O10>=80%,"Cumple","No Cumple") -> Cumple | Q10: =IF(O10=80%,N10*70%,IF(AND(O10>=81%,O10<=90%),N10*80%,IF(AND(O10>=91%,O10<=95%),N10*90%,IF(O10=96%,N10*96%,IF(O10=97%,N10*97%,IF(O10=98%,N10*98%,IF(O10=99%,N10*99%,IF(O10=100%,N10,0)))))))) -> 150000 | R10: =+$F$4*$R$3 -> 50000 | S10: =+VLOOKUP(C10,Indicadores!B:Q,15,FALSE) -> 0.53333333 | T10: =IF(S10>=80%,"Cumple","No Cumple") -> No Cumple | U10: =IF(S10=80%,R10*70%,IF(AND(S10>=81%,S10<=90%),R10*80%,IF(AND(S10>=91%,S10<=95%),R10*90%,IF(S10=96%,R10*96%,IF(S10=97%,R10*97%,IF(S10=98%,R10*98%,IF(S10=99%,R10*99%,IF(S10=100%,R10,0)))))))) -> 0 | V10: =+$F$4*$V$3 -> 50000 | W10: =+VLOOKUP(C10,Indicadores!B:V,21,FALSE) -> 1 | X10: =IF(W10>=100%,"Cumple","No Cumple") -> Cumple | Y10: =IF(W10=100%,V10,0) -> 50000 | Z10: =IF(AND(G10>=70%,K10>=70%),"SI","NO") -> SI | AA10: =+IF(Z10="SI",Q10+U10+Y10,0) -> 200000
B11: REGIONAL BOGOTA | C11: CTR_14 | D11: ANYI MAYERLIE ORJUELA | E11: ADRIANA MARCELA DIAZ RICO | F11: =+$F$4*$G$3 -> 0 | G11: =+VLOOKUP(C11,Indicadores!B:C,2,FALSE) -> 0.4869 | H11: =IF(G11>=70%,"Cumple","No Cumple") -> No Cumple | I11: =+IF(G11>=95%,F11*G11,0) -> 0 | J11: =+$F$4*$J$3 -> 0 | K11: =+VLOOKUP(C11,Indicadores!B:F,5,FALSE) -> 1 | L11: =IF(K11>=70%,"Cumple","No Cumple") -> Cumple | M11: =+IF(K11>=95%,J11*K11,0) -> 0 | N11: =+$F$4*$N$3 -> 150000 | O11: =+VLOOKUP(C11,Indicadores!B:P,14,FALSE) -> 0.0847 | P11: =IF(O11>=80%,"Cumple","No Cumple") -> No Cumple | Q11: =IF(O11=80%,N11*70%,IF(AND(O11>=81%,O11<=90%),N11*80%,IF(AND(O11>=91%,O11<=95%),N11*90%,IF(O11=96%,N11*96%,IF(O11=97%,N11*97%,IF(O11=98%,N11*98%,IF(O11=99%,N11*99%,IF(O11=100%,N11,0)))))))) -> 0 | R11: =+$F$4*$R$3 -> 50000 | S11: =+VLOOKUP(C11,Indicadores!B:Q,15,FALSE) -> 0.30066667 | T11: =IF(S11>=80%,"Cumple","No Cumple") -> No Cumple | U11: =IF(S11=80%,R11*70%,IF(AND(S11>=81%,S11<=90%),R11*80%,IF(AND(S11>=91%,S11<=95%),R11*90%,IF(S11=96%,R11*96%,IF(S11=97%,R11*97%,IF(S11=98%,R11*98%,IF(S11=99%,R11*99%,IF(S11=100%,R11,0)))))))) -> 0 | V11: =+$F$4*$V$3 -> 50000 | W11: =+VLOOKUP(C11,Indicadores!B:V,21,FALSE) -> 0.38985 | X11: =IF(W11>=100%,"Cumple","No Cumple") -> No Cumple | Y11: =IF(W11=100%,V11,0) -> 0 | Z11: =IF(AND(G11>=70%,K11>=70%),"SI","NO") -> NO | AA11: =+IF(Z11="SI",Q11+U11+Y11,0) -> 0
B12: REGIONAL BOGOTA | C12: CTR_15 | D12: ANYI MAYERLIE ORJUELA | E12: ADRIANA MARCELA DIAZ RICO | F12: =+$F$4*$G$3 -> 0 | G12: =+VLOOKUP(C12,Indicadores!B:C,2,FALSE) -> 0.78221818 | H12: =IF(G12>=70%,"Cumple","No Cumple") -> Cumple | I12: =+IF(G12>=95%,F12*G12,0) -> 0 | J12: =+$F$4*$J$3 -> 0 | K12: =+VLOOKUP(C12,Indicadores!B:F,5,FALSE) -> 1 | L12: =IF(K12>=70%,"Cumple","No Cumple") -> Cumple | M12: =+IF(K12>=95%,J12*K12,0) -> 0 | N12: =+$F$4*$N$3 -> 150000 | O12: =+VLOOKUP(C12,Indicadores!B:P,14,FALSE) -> 0.989 | P12: =IF(O12>=80%,"Cumple","No Cumple") -> Cumple | Q12: =IF(O12=80%,N12*70%,IF(AND(O12>=81%,O12<=90%),N12*80%,IF(AND(O12>=91%,O12<=95%),N12*90%,IF(O12=96%,N12*96%,IF(O12=97%,N12*97%,IF(O12=98%,N12*98%,IF(O12=99%,N12*99%,IF(O12=100%,N12,0)))))))) -> 0 | R12: =+$F$4*$R$3 -> 50000 | S12: =+VLOOKUP(C12,Indicadores!B:Q,15,FALSE) -> 0.56656667 | T12: =IF(S12>=80%,"Cumple","No Cumple") -> No Cumple | U12: =IF(S12=80%,R12*70%,IF(AND(S12>=81%,S12<=90%),R12*80%,IF(AND(S12>=91%,S12<=95%),R12*90%,IF(S12=96%,R12*96%,IF(S12=97%,R12*97%,IF(S12=98%,R12*98%,IF(S12=99%,R12*99%,IF(S12=100%,R12,0)))))))) -> 0 | V12: =+$F$4*$V$3 -> 50000 | W12: =+VLOOKUP(C12,Indicadores!B:V,21,FALSE) -> 0.4945 | X12: =IF(W12>=100%,"Cumple","No Cumple") -> No Cumple | Y12: =IF(W12=100%,V12,0) -> 0 | Z12: =IF(AND(G12>=70%,K12>=70%),"SI","NO") -> SI | AA12: =+IF(Z12="SI",Q12+U12+Y12,0) -> 0
B13: REGIONAL BOGOTA | C13: CTR_16 | D13: ANYI MAYERLIE ORJUELA | E13: ADRIANA MARCELA DIAZ RICO | F13: =+$F$4*$G$3 -> 0 | G13: =+VLOOKUP(C13,Indicadores!B:C,2,FALSE) -> 0.7544 | H13: =IF(G13>=70%,"Cumple","No Cumple") -> Cumple | I13: =+IF(G13>=95%,F13*G13,0) -> 0 | J13: =+$F$4*$J$3 -> 0 | K13: =+VLOOKUP(C13,Indicadores!B:F,5,FALSE) -> 0.92857143 | L13: =IF(K13>=70%,"Cumple","No Cumple") -> Cumple | M13: =+IF(K13>=95%,J13*K13,0) -> 0 | N13: =+$F$4*$N$3 -> 150000 | O13: =+VLOOKUP(C13,Indicadores!B:P,14,FALSE) -> 0.9403 | P13: =IF(O13>=80%,"Cumple","No Cumple") -> Cumple | Q13: =IF(O13=80%,N13*70%,IF(AND(O13>=81%,O13<=90%),N13*80%,IF(AND(O13>=91%,O13<=95%),N13*90%,IF(O13=96%,N13*96%,IF(O13=97%,N13*97%,IF(O13=98%,N13*98%,IF(O13=99%,N13*99%,IF(O13=100%,N13,0)))))))) -> 135000 | R13: =+$F$4*$R$3 -> 50000 | S13: =+VLOOKUP(C13,Indicadores!B:Q,15,FALSE) -> 0.369 | T13: =IF(S13>=80%,"Cumple","No Cumple") -> No Cumple | U13: =IF(S13=80%,R13*70%,IF(AND(S13>=81%,S13<=90%),R13*80%,IF(AND(S13>=91%,S13<=95%),R13*90%,IF(S13=96%,R13*96%,IF(S13=97%,R13*97%,IF(S13=98%,R13*98%,IF(S13=99%,R13*99%,IF(S13=100%,R13,0)))))))) -> 0 | V13: =+$F$4*$V$3 -> 50000 | W13: =+VLOOKUP(C13,Indicadores!B:V,21,FALSE) -> 0.9403 | X13: =IF(W13>=100%,"Cumple","No Cumple") -> No Cumple | Y13: =IF(W13=100%,V13,0) -> 0 | Z13: =IF(AND(G13>=70%,K13>=70%),"SI","NO") -> SI | AA13: =+IF(Z13="SI",Q13+U13+Y13,0) -> 135000
B14: REGIONAL BOGOTA | C14: CTR_2 | D14: ANYI MAYERLIE ORJUELA | E14: ADRIANA MARCELA DIAZ RICO | F14: =+$F$4*$G$3 -> 0 | G14: =+VLOOKUP(C14,Indicadores!B:C,2,FALSE) -> 0.73967273 | H14: =IF(G14>=70%,"Cumple","No Cumple") -> Cumple | I14: =+IF(G14>=95%,F14*G14,0) -> 0 | J14: =+$F$4*$J$3 -> 0 | K14: =+VLOOKUP(C14,Indicadores!B:F,5,FALSE) -> 0.5 | L14: =IF(K14>=70%,"Cumple","No Cumple") -> No Cumple | M14: =+IF(K14>=95%,J14*K14,0) -> 0 | N14: =+$F$4*$N$3 -> 150000 | O14: =+VLOOKUP(C14,Indicadores!B:P,14,FALSE) -> 0.8182 | P14: =IF(O14>=80%,"Cumple","No Cumple") -> Cumple | Q14: =IF(O14=80%,N14*70%,IF(AND(O14>=81%,O14<=90%),N14*80%,IF(AND(O14>=91%,O14<=95%),N14*90%,IF(O14=96%,N14*96%,IF(O14=97%,N14*97%,IF(O14=98%,N14*98%,IF(O14=99%,N14*99%,IF(O14=100%,N14,0)))))))) -> 120000 | R14: =+$F$4*$R$3 -> 50000 | S14: =+VLOOKUP(C14,Indicadores!B:Q,15,FALSE) -> 0.66163333 | T14: =IF(S14>=80%,"Cumple","No Cumple") -> No Cumple | U14: =IF(S14=80%,R14*70%,IF(AND(S14>=81%,S14<=90%),R14*80%,IF(AND(S14>=91%,S14<=95%),R14*90%,IF(S14=96%,R14*96%,IF(S14=97%,R14*97%,IF(S14=98%,R14*98%,IF(S14=99%,R14*99%,IF(S14=100%,R14,0)))))))) -> 0 | V14: =+$F$4*$V$3 -> 50000 | W14: =+VLOOKUP(C14,Indicadores!B:V,21,FALSE) -> 0.4091 | X14: =IF(W14>=100%,"Cumple","No Cumple") -> No Cumple | Y14: =IF(W14=100%,V14,0) -> 0 | Z14: =IF(AND(G14>=70%,K14>=70%),"SI","NO") -> NO | AA14: =+IF(Z14="SI",Q14+U14+Y14,0) -> 0
